Workbook

Sheet FOOD WASTAGE-SANNAI MESS
A1: FOOD WASTAGE REPORT-APRIL TO MARCH-2023-2024
A2: MESS WISE REPORT-SANNASI MESS
A3: S.NO | B3: Break Fast | C3: Break Fast | D3: Lunch | E3: Snacks with Tea | F3: Dinner | G3: TOTAL FOOD WASTAGE
A4: 1 | B4: Apr-2023 | C4: 1427 | D4: 10643 | E4: 0 | F4: 10890 | G4: =SUM(C4:F4) -> 22960
A5: 2 | B5: May-2023 | C5: 1280 | D5: 10980 | E5: 0 | F5: 11785 | G5: =SUM(C5:F5) -> 24045
A6: 3 | B6: Jun-2023 | C6: 542 | D6: 4729 | E6: 0 | F6: 5537 | G6: =SUM(C6:F6) -> 10808
A7: 4 | B7: Jul-2023 | C7: 1483 | D7: 2564 | E7: 0 | F7: 2478 | G7: =SUM(C7:F7) -> 6525
A8: 5 | B8: Aug-2023 | C8: 1147 | D8: 4944 | E8: 0 | F8: 5520 | G8: =SUM(C8:F8) -> 11611
A9: 6 | B9: Sep-2023 | C9: 954 | D9: 4156 | E9: 0 | F9: 5026 | G9: =SUM(C9:F9) -> 10136
A10: 7 | B10: Oct-2023 | C10: 894 | D10: 4514 | E10: 0 | F10: 5478 | G10: =SUM(C10:F10) -> 10886
A11: 8 | B11: Nov-2023 | C11: 1041 | D11: 4501 | E11: 0 | F11: 5820 | G11: =SUM(C11:F11) -> 11362
A12: 9 | B12: Dec-2023 | C12: 694 | D12: 3254 | E12: 0 | F12: 4447 | G12: =SUM(C12:F12) -> 8395
A13: 10 | B13: Jan-2024 | C13: 765 | D13: 3937 | E13: 0 | F13: 4753 | G13: =SUM(C13:F13) -> 9455
A14: 11 | B14: Feb-2024 | C14: 1120 | D14: 3907 | E14: 0 | F14: 5306 | G14: =SUM(C14:F14) -> 10333
A15: 12 | B15: Mar-2024 | C15: 876 | D15: 4498 | E15: 0 | F15: 5796 | G15: =SUM(C15:F15) -> 11170
B16: Grand Total | C16: =SUBTOTAL(9,C4:C15) -> 12223 | D16: =SUBTOTAL(9,D4:D15) -> 62627 | E16: =SUBTOTAL(9,E4:E15) -> 0 | F16: =SUBTOTAL(9,F4:F15) -> 72836 | G16: =SUBTOTAL(9,G4:G15) -> 147686

Sheet PLATE COUNT -SANNAI MESS
A1: STUDENT PLATE COUNT REPORT-APRIL TO MARCH-2023-2024
A2: PLATE COUNT REPORT-SANNASI MESS
A3: S.NO | B3: Break Fast | C3: Break Fast | D3: Lunch | E3: Snacks with Tea | F3: Dinner | G3: Total Plate Count
A4: 1 | B4: Apr-2023 | C4: 48200 | D4: 121200 | E4: 130150 | F4: 130150 | G4: =SUM(C4:F4) -> 429700
A5: 2 | B5: May-2023 | C5: 50086 | D5: 107468 | E5: 115715 | F5: 115715 | G5: =SUM(C5:F5) -> 388984
A6: 3 | B6: Jun-2023 | C6: 23055 | D6: 30900 | E6: 29387 | F6: 29387 | G6: =SUM(C6:F6) -> 112729
A7: 4 | B7: Jul-2023 | C7: 12800 | D7: 13840 | E7: 13830 | F7: 13930 | G7: =SUM(C7:F7) -> 54400
A8: 5 | B8: Aug-2023 | C8: 78261 | D8: 148950 | E8: 155693 | F8: 161800 | G8: =SUM(C8:F8) -> 544704
A9: 6 | B9: Sep-2023 | C9: 70200 | D9: 137020 | E9: 147900 | F9: 149800 | G9: =SUM(C9:F9) -> 504920
A10: 7 | B10: Oct-2023 | C10: 69470 | D10: 143600 | E10: 155150 | F10: 155150 | G10: =SUM(C10:F10) -> 523370
A11: 8 | B11: Nov-2023 | C11: 66970 | D11: 147220 | E11: 166910 | F11: 166910 | G11: =SUM(C11:F11) -> 548010
A12: 9 | B12: Dec-2023 | C12: 41510 | D12: 85051 | E12: 78921 | F12: 79121 | G12: =SUM(C12:F12) -> 284603
A13: 10 | B13: Jan-2024 | C13: 63766 | D13: 120981 | E13: 112366 | F13: 113466 | G13: =SUM(C13:F13) -> 410579
A14: 11 | B14: Feb-2024 | C14: 54206 | D14: 155689 | E14: 168926 | F14: 165326 | G14: =SUM(C14:F14) -> 544147
A15: 12 | B15: Mar-2024 | C15: 51533 | D15: 162869 | E15: 171597 | F15: 171598 | G15: =SUM(C15:F15) -> 557597
B16: Grand Total | C16: =SUBTOTAL(9,C4:C15) -> 630057 | D16: =SUBTOTAL(9,D4:D15) -> 1374788 | E16: =SUBTOTAL(9,E4:E15) -> 1446545 | F16: =SUBTOTAL(9,F4:F15) -> 1452353 | G16: =SUBTOTAL(9,G4:G15) -> 4903743

Sheet REPORT - SANNASI MESS
A1: SRM IST HOSTEL MESS
A2: SANNASI -MESS PLATE COUNT& FOOD WASTAGE -APRIL TO MARCH-2023-2024
C3: Plate Count | D3: Food Wastage | E3: Percantage of Food Wastage % | F3: Plate Count | G3: Food Wastage | H3: Percantage of Food Wastage % | I3: Plate Count | J3: Food Wastage | K3: Percantage of Food Wastage % | L3: Plate Count | M3: Food Wastage | N3: Percantage of Food Wastage % | P3: SRM IST HOSTEL MESS
A4: S.NO | B4: MONTH WISE | C4: Break Fast | D4: Break Fast | E4: Break Fast | F4: Lunch | G4: Lunch | H4: Lunch | I4: Snacks with Tea | J4: Snacks with Tea | K4: Snacks with Tea | L4: Dinner | M4: Dinner | N4: Dinner | P4: SANNASI MESS-PERCEANTAGE OF FOOD WASTAGE-APRIL TO MARCH-2023 TO 2024
A5: 1 | B5: Apr-2023 | C5: =VLOOKUP($B$5:$B$16,'PLATE COUNT -SANNAI MESS'!$B$4:$F$15,2,0) -> 48200 | D5: =VLOOKUP($B$5:$B$16,'FOOD WASTAGE-SANNAI MESS'!$B$4:$F$15,2,0) -> 1427 | E5: =SUM(D5/C5*100) -> 2.9605809 | F5: =VLOOKUP($B$5:$B$16,'PLATE COUNT -SANNAI MESS'!$B$4:$F$15,3,0) -> 121200 | G5: =VLOOKUP($B$5:$B$16,'FOOD WASTAGE-SANNAI MESS'!$B$4:$F$15,3,0) -> 10643 | H5: =SUM(G5/F5*100) -> 8.7813531 | I5: =VLOOKUP($B$5:$B$16,'PLATE COUNT -SANNAI MESS'!$B$4:$F$15,4,0) -> 130150 | J5: =VLOOKUP($B$5:$B$16,'FOOD WASTAGE-SANNAI MESS'!$B$4:$F$15,4,0) -> 0 | K5: =IFERROR(SUM(I5/J5),"0") -> 0 | L5: =VLOOKUP($B$5:$B$16,'PLATE COUNT -SANNAI MESS'!$B$4:$F$15,5,0) -> 130150 | M5: =VLOOKUP($B$5:$B$16,'FOOD WASTAGE-SANNAI MESS'!$B$4:$F$15,5,0) -> 10890 | N5: =SUM(M5/L5*100) -> 8.3672685 | P5: MONTH WISE | Q5: Break Fast | R5: Lunch | S5: Snaks with Tea | T5: Dinner | U5: MONTH WISE AVERAGE
A6: 2 | B6: May-2023 | C6: =VLOOKUP($B$5:$B$16,'PLATE COUNT -SANNAI MESS'!$B$4:$F$15,2,0) -> 50086 | D6: =VLOOKUP($B$5:$B$16,'FOOD WASTAGE-SANNAI MESS'!$B$4:$F$15,2,0) -> 1280 | E6: =SUM(D6/C6*100) -> 2.5556044 | F6: =VLOOKUP($B$5:$B$16,'PLATE COUNT -SANNAI MESS'!$B$4:$F$15,3,0) -> 107468 | G6: =VLOOKUP($B$5:$B$16,'FOOD WASTAGE-SANNAI MESS'!$B$4:$F$15,3,0) -> 10980 | H6: =SUM(G6/F6*100) -> 10.216995 | I6: =VLOOKUP($B$5:$B$16,'PLATE COUNT -SANNAI MESS'!$B$4:$F$15,4,0) -> 115715 | J6: =VLOOKUP($B$5:$B$16,'FOOD WASTAGE-SANNAI MESS'!$B$4:$F$15,4,0) -> 0 | K6: =IFERROR(SUM(I6/J6),"0") -> 0 | L6: =VLOOKUP($B$5:$B$16,'PLATE COUNT -SANNAI MESS'!$B$4:$F$15,5,0) -> 115715 | M6: =VLOOKUP($B$5:$B$16,'FOOD WASTAGE-SANNAI MESS'!$B$4:$F$15,5,0) -> 11785 | N6: =SUM(M6/L6*100) -> 10.184505 | P6: Apr-2023 | Q6: =VLOOKUP($P$6:$P$17,$B$4:$N$16,4,0) -> 2.9605809 | R6: =VLOOKUP($P$6:$P$17,$B$4:$N$16,7,0) -> 8.7813531 | S6: =VLOOKUP($P$6:$P$17,$B$4:$N$16,10,0) -> 0 | T6: =VLOOKUP($P$6:$P$17,$B$4:$N$16,13,0) -> 8.3672685 | U6: =SUM(Q6:T6)/4 -> 5.0273006
A7: 3 | B7: Jun-2023 | C7: =VLOOKUP($B$5:$B$16,'PLATE COUNT -SANNAI MESS'!$B$4:$F$15,2,0) -> 23055 | D7: =VLOOKUP($B$5:$B$16,'FOOD WASTAGE-SANNAI MESS'!$B$4:$F$15,2,0) -> 542 | E7: =SUM(D7/C7*100) -> 2.3509 | F7: =VLOOKUP($B$5:$B$16,'PLATE COUNT -SANNAI MESS'!$B$4:$F$15,3,0) -> 30900 | G7: =VLOOKUP($B$5:$B$16,'FOOD WASTAGE-SANNAI MESS'!$B$4:$F$15,3,0) -> 4729 | H7: =SUM(G7/F7*100) -> 15.304207 | I7: =VLOOKUP($B$5:$B$16,'PLATE COUNT -SANNAI MESS'!$B$4:$F$15,4,0) -> 29387 | J7: =VLOOKUP($B$5:$B$16,'FOOD WASTAGE-SANNAI MESS'!$B$4:$F$15,4,0) -> 0 | K7: =IFERROR(SUM(I7/J7),"0") -> 0 | L7: =VLOOKUP($B$5:$B$16,'PLATE COUNT -SANNAI MESS'!$B$4:$F$15,5,0) -> 29387 | M7: =VLOOKUP($B$5:$B$16,'FOOD WASTAGE-SANNAI MESS'!$B$4:$F$15,5,0) -> 5537 | N7: =SUM(M7/L7*100) -> 18.841665 | P7: May-2023 | Q7: =VLOOKUP($P$6:$P$17,$B$4:$N$16,4,0) -> 2.5556044 | R7: =VLOOKUP($P$6:$P$17,$B$4:$N$16,7,0) -> 10.216995 | S7: =VLOOKUP($P$6:$P$17,$B$4:$N$16,10,0) -> 0 | T7: =VLOOKUP($P$6:$P$17,$B$4:$N$16,13,0) -> 10.184505 | U7: =SUM(Q7:T7)/4 -> 5.7392761
A8: 4 | B8: Jul-2023 | C8: =VLOOKUP($B$5:$B$16,'PLATE COUNT -SANNAI MESS'!$B$4:$F$15,2,0) -> 12800 | D8: =VLOOKUP($B$5:$B$16,'FOOD WASTAGE-SANNAI MESS'!$B$4:$F$15,2,0) -> 1483 | E8: =SUM(D8/C8*100) -> 11.585938 | F8: =VLOOKUP($B$5:$B$16,'PLATE COUNT -SANNAI MESS'!$B$4:$F$15,3,0) -> 13840 | G8: =VLOOKUP($B$5:$B$16,'FOOD WASTAGE-SANNAI MESS'!$B$4:$F$15,3,0) -> 2564 | H8: =SUM(G8/F8*100) -> 18.526012 | I8: =VLOOKUP($B$5:$B$16,'PLATE COUNT -SANNAI MESS'!$B$4:$F$15,4,0) -> 13830 | J8: =VLOOKUP($B$5:$B$16,'FOOD WASTAGE-SANNAI MESS'!$B$4:$F$15,4,0) -> 0 | K8: =IFERROR(SUM(I8/J8),"0") -> 0 | L8: =VLOOKUP($B$5:$B$16,'PLATE COUNT -SANNAI MESS'!$B$4:$F$15,5,0) -> 13930 | M8: =VLOOKUP($B$5:$B$16,'FOOD WASTAGE-SANNAI MESS'!$B$4:$F$15,5,0) -> 2478 | N8: =SUM(M8/L8*100) -> 17.788945 | P8: Jun-2023 | Q8: =VLOOKUP($P$6:$P$17,$B$4:$N$16,4,0) -> 2.3509 | R8: =VLOOKUP($P$6:$P$17,$B$4:$N$16,7,0) -> 15.304207 | S8: =VLOOKUP($P$6:$P$17,$B$4:$N$16,10,0) -> 0 | T8: =VLOOKUP($P$6:$P$17,$B$4:$N$16,13,0) -> 18.841665 | U8: =SUM(Q8:T8)/4 -> 9.124193
A9: 5 | B9: Aug-2023 | C9: =VLOOKUP($B$5:$B$16,'PLATE COUNT -SANNAI MESS'!$B$4:$F$15,2,0) -> 78261 | D9: =VLOOKUP($B$5:$B$16,'FOOD WASTAGE-SANNAI MESS'!$B$4:$F$15,2,0) -> 1147 | E9: =SUM(D9/C9*100) -> 1.4656087 | F9: =VLOOKUP($B$5:$B$16,'PLATE COUNT -SANNAI MESS'!$B$4:$F$15,3,0) -> 148950 | G9: =VLOOKUP($B$5:$B$16,'FOOD WASTAGE-SANNAI MESS'!$B$4:$F$15,3,0) -> 4944 | H9: =SUM(G9/F9*100) -> 3.3192346 | I9: =VLOOKUP($B$5:$B$16,'PLATE COUNT -SANNAI MESS'!$B$4:$F$15,4,0) -> 155693 | J9: =VLOOKUP($B$5:$B$16,'FOOD WASTAGE-SANNAI MESS'!$B$4:$F$15,4,0) -> 0 | K9: =IFERROR(SUM(I9/J9),"0") -> 0 | L9: =VLOOKUP($B$5:$B$16,'PLATE COUNT -SANNAI MESS'!$B$4:$F$15,5,0) -> 161800 | M9: =VLOOKUP($B$5:$B$16,'FOOD WASTAGE-SANNAI MESS'!$B$4:$F$15,5,0) -> 5520 | N9: =SUM(M9/L9*100) -> 3.4116193 | P9: Jul-2023 | Q9: =VLOOKUP($P$6:$P$17,$B$4:$N$16,4,0) -> 11.585938 | R9: =VLOOKUP($P$6:$P$17,$B$4:$N$16,7,0) -> 18.526012 | S9: =VLOOKUP($P$6:$P$17,$B$4:$N$16,10,0) -> 0 | T9: =VLOOKUP($P$6:$P$17,$B$4:$N$16,13,0) -> 17.788945 | U9: =SUM(Q9:T9)/4 -> 11.975223
A10: 6 | B10: Sep-2023 | C10: =VLOOKUP($B$5:$B$16,'PLATE COUNT -SANNAI MESS'!$B$4:$F$15,2,0) -> 70200 | D10: =VLOOKUP($B$5:$B$16,'FOOD WASTAGE-SANNAI MESS'!$B$4:$F$15,2,0) -> 954 | E10: =SUM(D10/C10*100) -> 1.3589744 | F10: =VLOOKUP($B$5:$B$16,'PLATE COUNT -SANNAI MESS'!$B$4:$F$15,3,0) -> 137020 | G10: =VLOOKUP($B$5:$B$16,'FOOD WASTAGE-SANNAI MESS'!$B$4:$F$15,3,0) -> 4156 | H10: =SUM(G10/F10*100) -> 3.0331338 | I10: =VLOOKUP($B$5:$B$16,'PLATE COUNT -SANNAI MESS'!$B$4:$F$15,4,0) -> 147900 | J10: =VLOOKUP($B$5:$B$16,'FOOD WASTAGE-SANNAI MESS'!$B$4:$F$15,4,0) -> 0 | K10: =IFERROR(SUM(I10/J10),"0") -> 0 | L10: =VLOOKUP($B$5:$B$16,'PLATE COUNT -SANNAI MESS'!$B$4:$F$15,5,0) -> 149800 | M10: =VLOOKUP($B$5:$B$16,'FOOD WASTAGE-SANNAI MESS'!$B$4:$F$15,5,0) -> 5026 | N10: =SUM(M10/L10*100) -> 3.3551402 | P10: Aug-2023 | Q10: =VLOOKUP($P$6:$P$17,$B$4:$N$16,4,0) -> 1.4656087 | R10: =VLOOKUP($P$6:$P$17,$B$4:$N$16,7,0) -> 3.3192346 | S10: =VLOOKUP($P$6:$P$17,$B$4:$N$16,10,0) -> 0 | T10: =VLOOKUP($P$6:$P$17,$B$4:$N$16,13,0) -> 3.4116193 | U10: =SUM(Q10:T10)/4 -> 2.0491156
A11: 7 | B11: Oct-2023 | C11: =VLOOKUP($B$5:$B$16,'PLATE COUNT -SANNAI MESS'!$B$4:$F$15,2,0) -> 69470 | D11: =VLOOKUP($B$5:$B$16,'FOOD WASTAGE-SANNAI MESS'!$B$4:$F$15,2,0) -> 894 | E11: =SUM(D11/C11*100) -> 1.2868864 | F11: =VLOOKUP($B$5:$B$16,'PLATE COUNT -SANNAI MESS'!$B$4:$F$15,3,0) -> 143600 | G11: =VLOOKUP($B$5:$B$16,'FOOD WASTAGE-SANNAI MESS'!$B$4:$F$15,3,0) -> 4514 | H11: =SUM(G11/F11*100) -> 3.143454 | I11: =VLOOKUP($B$5:$B$16,'PLATE COUNT -SANNAI MESS'!$B$4:$F$15,4,0) -> 155150 | J11: =VLOOKUP($B$5:$B$16,'FOOD WASTAGE-SANNAI MESS'!$B$4:$F$15,4,0) -> 0 | K11: =IFERROR(SUM(I11/J11),"0") -> 0 | L11: =VLOOKUP($B$5:$B$16,'PLATE COUNT -SANNAI MESS'!$B$4:$F$15,5,0) -> 155150 | M11: =VLOOKUP($B$5:$B$16,'FOOD WASTAGE-SANNAI MESS'!$B$4:$F$15,5,0) -> 5478 | N11: =SUM(M11/L11*100) -> 3.5307767 | P11: Sep-2023 | Q11: =VLOOKUP($P$6:$P$17,$B$4:$N$16,4,0) -> 1.3589744 | R11: =VLOOKUP($P$6:$P$17,$B$4:$N$16,7,0) -> 3.0331338 | S11: =VLOOKUP($P$6:$P$17,$B$4:$N$16,10,0) -> 0 | T11: =VLOOKUP($P$6:$P$17,$B$4:$N$16,13,0) -> 3.3551402 | U11: =SUM(Q11:T11)/4 -> 1.9368121
A12: 8 | B12: Nov-2023 | C12: =VLOOKUP($B$5:$B$16,'PLATE COUNT -SANNAI MESS'!$B$4:$F$15,2,0) -> 66970 | D12: =VLOOKUP($B$5:$B$16,'FOOD WASTAGE-SANNAI MESS'!$B$4:$F$15,2,0) -> 1041 | E12: =SUM(D12/C12*100) -> 1.5544274 | F12: =VLOOKUP($B$5:$B$16,'PLATE COUNT -SANNAI MESS'!$B$4:$F$15,3,0) -> 147220 | G12: =VLOOKUP($B$5:$B$16,'FOOD WASTAGE-SANNAI MESS'!$B$4:$F$15,3,0) -> 4501 | H12: =SUM(G12/F12*100) -> 3.0573292 | I12: =VLOOKUP($B$5:$B$16,'PLATE COUNT -SANNAI MESS'!$B$4:$F$15,4,0) -> 166910 | J12: =VLOOKUP($B$5:$B$16,'FOOD WASTAGE-SANNAI MESS'!$B$4:$F$15,4,0) -> 0 | K12: =IFERROR(SUM(I12/J12),"0") -> 0 | L12: =VLOOKUP($B$5:$B$16,'PLATE COUNT -SANNAI MESS'!$B$4:$F$15,5,0) -> 166910 | M12: =VLOOKUP($B$5:$B$16,'FOOD WASTAGE-SANNAI MESS'!$B$4:$F$15,5,0) -> 5820 | N12: =SUM(M12/L12*100) -> 3.4869091 | P12: Oct-2023 | Q12: =VLOOKUP($P$6:$P$17,$B$4:$N$16,4,0) -> 1.2868864 | R12: =VLOOKUP($P$6:$P$17,$B$4:$N$16,7,0) -> 3.143454 | S12: =VLOOKUP($P$6:$P$17,$B$4:$N$16,10,0) -> 0 | T12: =VLOOKUP($P$6:$P$17,$B$4:$N$16,13,0) -> 3.5307767 | U12: =SUM(Q12:T12)/4 -> 1.9902793
A13: 9 | B13: Dec-2023 | C13: =VLOOKUP($B$5:$B$16,'PLATE COUNT -SANNAI MESS'!$B$4:$F$15,2,0) -> 41510 | D13: =VLOOKUP($B$5:$B$16,'FOOD WASTAGE-SANNAI MESS'!$B$4:$F$15,2,0) -> 694 | E13: =SUM(D13/C13*100) -> 1.6718863 | F13: =VLOOKUP($B$5:$B$16,'PLATE COUNT -SANNAI MESS'!$B$4:$F$15,3,0) -> 85051 | G13: =VLOOKUP($B$5:$B$16,'FOOD WASTAGE-SANNAI MESS'!$B$4:$F$15,3,0) -> 3254 | H13: =SUM(G13/F13*100) -> 3.8259397 | I13: =VLOOKUP($B$5:$B$16,'PLATE COUNT -SANNAI MESS'!$B$4:$F$15,4,0) -> 78921 | J13: =VLOOKUP($B$5:$B$16,'FOOD WASTAGE-SANNAI MESS'!$B$4:$F$15,4,0) -> 0 | K13: =IFERROR(SUM(I13/J13),"0") -> 0 | L13: =VLOOKUP($B$5:$B$16,'PLATE COUNT -SANNAI MESS'!$B$4:$F$15,5,0) -> 79121 | M13: =VLOOKUP($B$5:$B$16,'FOOD WASTAGE-SANNAI MESS'!$B$4:$F$15,5,0) -> 4447 | N13: =SUM(M13/L13*100) -> 5.6205053 | P13: Nov-2023 | Q13: =VLOOKUP($P$6:$P$17,$B$4:$N$16,4,0) -> 1.5544274 | R13: =VLOOKUP($P$6:$P$17,$B$4:$N$16,7,0) -> 3.0573292 | S13: =VLOOKUP($P$6:$P$17,$B$4:$N$16,10,0) -> 0 | T13: =VLOOKUP($P$6:$P$17,$B$4:$N$16,13,0) -> 3.4869091 | U13: =SUM(Q13:T13)/4 -> 2.0246664
A14: 10 | B14: Jan-2024 | C14: =VLOOKUP($B$5:$B$16,'PLATE COUNT -SANNAI MESS'!$B$4:$F$15,2,0) -> 63766 | D14: =VLOOKUP($B$5:$B$16,'FOOD WASTAGE-SANNAI MESS'!$B$4:$F$15,2,0) -> 765 | E14: =SUM(D14/C14*100) -> 1.1996989 | F14: =VLOOKUP($B$5:$B$16,'PLATE COUNT -SANNAI MESS'!$B$4:$F$15,3,0) -> 120981 | G14: =VLOOKUP($B$5:$B$16,'FOOD WASTAGE-SANNAI MESS'!$B$4:$F$15,3,0) -> 3937 | H14: =SUM(G14/F14*100) -> 3.25423 | I14: =VLOOKUP($B$5:$B$16,'PLATE COUNT -SANNAI MESS'!$B$4:$F$15,4,0) -> 112366 | J14: =VLOOKUP($B$5:$B$16,'FOOD WASTAGE-SANNAI MESS'!$B$4:$F$15,4,0) -> 0 | K14: =IFERROR(SUM(I14/J14),"0") -> 0 | L14: =VLOOKUP($B$5:$B$16,'PLATE COUNT -SANNAI MESS'!$B$4:$F$15,5,0) -> 113466 | M14: =VLOOKUP($B$5:$B$16,'FOOD WASTAGE-SANNAI MESS'!$B$4:$F$15,5,0) -> 4753 | N14: =SUM(M14/L14*100) -> 4.18892 | P14: Dec-2023 | Q14: =VLOOKUP($P$6:$P$17,$B$4:$N$16,4,0) -> 1.6718863 | R14: =VLOOKUP($P$6:$P$17,$B$4:$N$16,7,0) -> 3.8259397 | S14: =VLOOKUP($P$6:$P$17,$B$4:$N$16,10,0) -> 0 | T14: =VLOOKUP($P$6:$P$17,$B$4:$N$16,13,0) -> 5.6205053 | U14: =SUM(Q14:T14)/4 -> 2.7795828
A15: 11 | B15: Feb-2024 | C15: =VLOOKUP($B$5:$B$16,'PLATE COUNT -SANNAI MESS'!$B$4:$F$15,2,0) -> 54206 | D15: =VLOOKUP($B$5:$B$16,'FOOD WASTAGE-SANNAI MESS'!$B$4:$F$15,2,0) -> 1120 | E15: =SUM(D15/C15*100) -> 2.0661919 | F15: =VLOOKUP($B$5:$B$16,'PLATE COUNT -SANNAI MESS'!$B$4:$F$15,3,0) -> 155689 | G15: =VLOOKUP($B$5:$B$16,'FOOD WASTAGE-SANNAI MESS'!$B$4:$F$15,3,0) -> 3907 | H15: =SUM(G15/F15*100) -> 2.5094901 | I15: =VLOOKUP($B$5:$B$16,'PLATE COUNT -SANNAI MESS'!$B$4:$F$15,4,0) -> 168926 | J15: =VLOOKUP($B$5:$B$16,'FOOD WASTAGE-SANNAI MESS'!$B$4:$F$15,4,0) -> 0 | K15: =IFERROR(SUM(I15/J15),"0") -> 0 | L15: =VLOOKUP($B$5:$B$16,'PLATE COUNT -SANNAI MESS'!$B$4:$F$15,5,0) -> 165326 | M15: =VLOOKUP($B$5:$B$16,'FOOD WASTAGE-SANNAI MESS'!$B$4:$F$15,5,0) -> 5306 | N15: =SUM(M15/L15*100) -> 3.2094165 | P15: Jan-2024 | Q15: =VLOOKUP($P$6:$P$17,$B$4:$N$16,4,0) -> 1.1996989 | R15: =VLOOKUP($P$6:$P$17,$B$4:$N$16,7,0) -> 3.25423 | S15: =VLOOKUP($P$6:$P$17,$B$4:$N$16,10,0) -> 0 | T15: =VLOOKUP($P$6:$P$17,$B$4:$N$16,13,0) -> 4.18892 | U15: =SUM(Q15:T15)/4 -> 2.1607122
A16: 12 | B16: Mar-2024 | C16: =VLOOKUP($B$5:$B$16,'PLATE COUNT -SANNAI MESS'!$B$4:$F$15,2,0) -> 51533 | D16: =VLOOKUP($B$5:$B$16,'FOOD WASTAGE-SANNAI MESS'!$B$4:$F$15,2,0) -> 876 | E16: =SUM(D16/C16*100) -> 1.6998816 | F16: =VLOOKUP($B$5:$B$16,'PLATE COUNT -SANNAI MESS'!$B$4:$F$15,3,0) -> 162869 | G16: =VLOOKUP($B$5:$B$16,'FOOD WASTAGE-SANNAI MESS'!$B$4:$F$15,3,0) -> 4498 | H16: =SUM(G16/F16*100) -> 2.7617288 | I16: =VLOOKUP($B$5:$B$16,'PLATE COUNT -SANNAI MESS'!$B$4:$F$15,4,0) -> 171597 | J16: =VLOOKUP($B$5:$B$16,'FOOD WASTAGE-SANNAI MESS'!$B$4:$F$15,4,0) -> 0 | K16: =IFERROR(SUM(I16/J16),"0") -> 0 | L16: =VLOOKUP($B$5:$B$16,'PLATE COUNT -SANNAI MESS'!$B$4:$F$15,5,0) -> 171598 | M16: =VLOOKUP($B$5:$B$16,'FOOD WASTAGE-SANNAI MESS'!$B$4:$F$15,5,0) -> 5796 | N16: =SUM(M16/L16*100) -> 3.3776617 | P16: Feb-2024 | Q16: =VLOOKUP($P$6:$P$17,$B$4:$N$16,4,0) -> 2.0661919 | R16: =VLOOKUP($P$6:$P$17,$B$4:$N$16,7,0) -> 2.5094901 | S16: =VLOOKUP($P$6:$P$17,$B$4:$N$16,10,0) -> 0 | T16: =VLOOKUP($P$6:$P$17,$B$4:$N$16,13,0) -> 3.2094165 | U16: =SUM(Q16:T16)/4 -> 1.9462746
B17: Grand Total | C17: =SUBTOTAL(9,C4:C16) -> 630057 | D17: =SUBTOTAL(9,D4:D16) -> 12223 | E17: =SUBTOTAL(9,E4:E16) -> 31.756578 | F17: =SUBTOTAL(9,F4:F16) -> 1374788 | G17: =SUBTOTAL(9,G4:G16) -> 62627 | H17: =SUBTOTAL(9,H4:H16) -> 77.733107 | I17: =SUBTOTAL(9,I4:I16) -> 1446545 | J17: =SUBTOTAL(9,J4:J16) -> 0 | ... N17: =SUBTOTAL(9,N4:N16) -> 85.363332 | P17: Mar-2024 | Q17: =VLOOKUP($P$6:$P$17,$B$4:$N$16,4,0) -> 1.6998816 | R17: =VLOOKUP($P$6:$P$17,$B$4:$N$16,7,0) -> 2.7617288 | S17: =VLOOKUP($P$6:$P$17,$B$4:$N$16,10,0) -> 0 | T17: =VLOOKUP($P$6:$P$17,$B$4:$N$16,13,0) -> 3.3776617 | U17: =SUM(Q17:T17)/4 -> 1.959818
P18: YEAR WISE FOOE WASTAGE SANNAI MESS (APRIL TO MARCH-2023 TO 2024) | U18: =SUM(U6:U17)/(12) -> 4.0594379

Sheet FOOD WASTAGE-D-MESS
A1: FOOD WASTAGE REPORT-APRIL TO MARCH-2023-2024
A2: MESS WISE REPORT-D- MESS
A3: S.NO | B3: MONTH WISE | C3: Break Fast | D3: Lunch | E3: Snacks with Tea | F3: Dinner | G3: TOTAL FOOD WASTAGE
A4: 1 | B4: Apr-2023 | C4: 1006 | D4: 3161 | E4: 0 | F4: 3175 | G4: =SUM(C4:F4) -> 7342
A5: 2 | B5: May-2023 | C5: 1023 | D5: 3024 | E5: 0 | F5: 3754 | G5: =SUM(C5:F5) -> 7801
A6: 3 | B6: Jun-2023 | C6: 15 | D6: 30 | E6: 0 | F6: 0 | G6: =SUM(C6:F6) -> 45
A7: 4 | B7: Jul-2023 | C7: 408 | D7: 1095 | E7: 0 | F7: 1117 | G7: =SUM(C7:F7) -> 2620
A8: 5 | B8: Aug-2023 | C8: 1181 | D8: 2453 | E8: 0 | F8: 2479 | G8: =SUM(C8:F8) -> 6113
A9: 6 | B9: Sep-2023 | C9: 1821 | D9: 3057 | E9: 0 | F9: 3583 | G9: =SUM(C9:F9) -> 8461
A10: 7 | B10: Oct-2023 | C10: 745 | D10: 2194 | E10: 0 | F10: 2264 | G10: =SUM(C10:F10) -> 5203
A11: 8 | B11: Nov-2023 | C11: 1006 | D11: 1977 | E11: 0 | F11: 2411 | G11: =SUM(C11:F11) -> 5394
A12: 9 | B12: Dec-2023 | C12: 205 | D12: 468 | E12: 0 | F12: 525 | G12: =SUM(C12:F12) -> 1198
A13: 10 | B13: Jan-2024 | C13: 0 | D13: 0 | E13: 0 | F13: 0 | G13: =SUM(C13:F13) -> 0
A14: 11 | B14: Feb-2024 | C14: 887 | D14: 1680 | E14: 0 | F14: 1867 | G14: =SUM(C14:F14) -> 4434
A15: 12 | B15: Mar-2024 | C15: 1013 | D15: 1720 | E15: 0 | F15: 2248 | G15: =SUM(C15:F15) -> 4981
B16: Grand Total | C16: =SUBTOTAL(9,C4:C15) -> 9310 | D16: =SUBTOTAL(9,D4:D15) -> 20859 | E16: =SUBTOTAL(9,E4:E15) -> 0 | F16: =SUBTOTAL(9,F4:F15) -> 23423 | G16: =SUBTOTAL(9,G4:G15) -> 53592

Sheet PLATE COUNT-D-MESS
A1: STUDENT PLATE COUNT REPORT-APRIL TO MARCH-2023-2024
A2: PLATE COUNT REPORT-D- MESS
A3: S.NO | B3: Break Fast | C3: Break Fast | D3: Lunch | E3: Snacks with Tea | F3: Dinner | G3: Total Plate Count
A4: 1 | B4: Apr-2023 | C4: 24455 | D4: 31425 | E4: 31350 | F4: 31360 | G4: =SUM(C4:F4) -> 118590
A5: 2 | B5: May-2023 | C5: 24240 | D5: 29827 | E5: 32415 | F5: 32415 | G5: =SUM(C5:F5) -> 118897
A6: 3 | B6: Jun-2023 | C6: 1360 | D6: 1655 | E6: 840 | F6: 840 | G6: =SUM(C6:F6) -> 4695
A7: 4 | B7: Jul-2023 | C7: 12465 | D7: 19740 | E7: 21090 | F7: 21090 | G7: =SUM(C7:F7) -> 74385
A8: 5 | B8: Aug-2023 | C8: 24580 | D8: 40135 | E8: 43220 | F8: 43100 | G8: =SUM(C8:F8) -> 151035
A9: 6 | B9: Sep-2023 | C9: 22752 | D9: 37614 | E9: 42907 | F9: 44457 | G9: =SUM(C9:F9) -> 147730
A10: 7 | B10: Oct-2023 | C10: 13135 | D10: 24626 | E10: 24790 | F10: 26240 | G10: =SUM(C10:F10) -> 88791
A11: 8 | B11: Nov-2023 | C11: 12493 | D11: 21964 | E11: 26996 | F11: 26996 | G11: =SUM(C11:F11) -> 88449
A12: 9 | B12: Dec-2023 | C12: 4976 | D12: 8673 | E12: 10715 | F12: 10715 | G12: =SUM(C12:F12) -> 35079
A13: 10 | B13: Jan-2024 | C13: 1395 | D13: 1250 | E13: 3480 | F13: 3480 | G13: =SUM(C13:F13) -> 9605
A14: 11 | B14: Feb-2024 | C14: 22356 | D14: 43656 | E14: 51643 | F14: 51643 | G14: =SUM(C14:F14) -> 169298
A15: 12 | B15: Mar-2024 | C15: 21414 | D15: 49248 | E15: 47967 | F15: 47967 | G15: =SUM(C15:F15) -> 166596
B16: Grand Total | C16: =SUBTOTAL(9,C4:C15) -> 185621 | D16: =SUBTOTAL(9,D4:D15) -> 309813 | E16: =SUBTOTAL(9,E4:E15) -> 337413 | F16: =SUBTOTAL(9,F4:F15) -> 340303 | G16: =SUBTOTAL(9,G4:G15) -> 1173150

Sheet REPORT -D-MESS
A1: SRM IST HOSTEL MESS
A2: D -MESS PLATE COUNT& FOOD WASTAGE -APRIL TO MARCH-2023-2024
C3: Plate Count | D3: Food Wastage | E3: Percantage of Food Wastage % | F3: Plate Count | G3: Food Wastage | H3: Percantage of Food Wastage % | I3: Plate Count | J3: Food Wastage | K3: Percantage of Food Wastage % | L3: Plate Count | M3: Food Wastage | N3: Percantage of Food Wastage % | P3: SRM IST HOSTEL MESS
A4: S.NO | B4: MONTH WISE | C4: Break Fast | D4: Break Fast | E4: Break Fast | F4: Lunch | G4: Lunch | H4: Lunch | I4: Snacks with Tea | J4: Snacks with Tea | K4: Snacks with Tea | L4: Dinner | M4: Dinner | N4: Dinner | P4: D- MESS-PERCEANTAGE OF FOOD WASTAGE-APRIL TO MARCH-2023 TO 2024
A5: 1 | B5: Apr-2023 | C5: =VLOOKUP($B$5:$B$16,'PLATE COUNT-D-MESS'!$B$4:$G$15,2,0) -> 24455 | D5: =VLOOKUP($B$5:$B$16,'FOOD WASTAGE-D-MESS'!$B$4:$G$15,2,0) -> 1006 | E5: =SUM(D5/C5*100) -> 4.1136782 | F5: =VLOOKUP($B$5:$B$16,'PLATE COUNT-D-MESS'!$B$4:$G$15,3,0) -> 31425 | G5: =VLOOKUP($B$5:$B$16,'FOOD WASTAGE-D-MESS'!$B$4:$G$15,3,0) -> 3161 | H5: =SUM(G5/F5*100) -> 10.05887 | I5: =VLOOKUP($B$5:$B$16,'PLATE COUNT-D-MESS'!$B$4:$G$15,4,0) -> 31350 | J5: =VLOOKUP($B$5:$B$16,'FOOD WASTAGE-D-MESS'!$B$4:$G$15,4,0) -> 0 | K5: =IFERROR(SUM(I5/J5),"0") -> 0 | L5: =VLOOKUP($B$5:$B$16,'PLATE COUNT-D-MESS'!$B$4:$G$15,5,0) -> 31360 | M5: =VLOOKUP($B$5:$B$16,'FOOD WASTAGE-D-MESS'!$B$4:$G$15,5,0) -> 3175 | N5: =SUM(M5/L5*100) -> 10.124362 | P5: MONTH WISE | Q5: Break Fast | R5: Lunch | S5: Snaks with Tea | T5: Dinner | U5: MONTH WISE AVERAGE
A6: 2 | B6: May-2023 | C6: =VLOOKUP($B$5:$B$16,'PLATE COUNT-D-MESS'!$B$4:$G$15,2,0) -> 24240 | D6: =VLOOKUP($B$5:$B$16,'FOOD WASTAGE-D-MESS'!$B$4:$G$15,2,0) -> 1023 | E6: =SUM(D6/C6*100) -> 4.220297 | F6: =VLOOKUP($B$5:$B$16,'PLATE COUNT-D-MESS'!$B$4:$G$15,3,0) -> 29827 | G6: =VLOOKUP($B$5:$B$16,'FOOD WASTAGE-D-MESS'!$B$4:$G$15,3,0) -> 3024 | H6: =SUM(G6/F6*100) -> 10.138465 | I6: =VLOOKUP($B$5:$B$16,'PLATE COUNT-D-MESS'!$B$4:$G$15,4,0) -> 32415 | J6: =VLOOKUP($B$5:$B$16,'FOOD WASTAGE-D-MESS'!$B$4:$G$15,4,0) -> 0 | K6: =IFERROR(SUM(I6/J6),"0") -> 0 | L6: =VLOOKUP($B$5:$B$16,'PLATE COUNT-D-MESS'!$B$4:$G$15,5,0) -> 32415 | M6: =VLOOKUP($B$5:$B$16,'FOOD WASTAGE-D-MESS'!$B$4:$G$15,5,0) -> 3754 | N6: =SUM(M6/L6*100) -> 11.581058 | P6: Apr-2023 | Q6: =VLOOKUP($P$6:$P$17,$B$4:$N$16,4,0) -> 4.1136782 | R6: =VLOOKUP($P$6:$P$17,$B$4:$N$16,7,0) -> 10.05887 | S6: =VLOOKUP($P$6:$P$17,$B$4:$N$16,10,0) -> 0 | T6: =VLOOKUP($P$6:$P$17,$B$4:$N$16,13,0) -> 10.124362 | U6: =SUM(Q6:T6)/4 -> 6.0742277
A7: 3 | B7: Jun-2023 | C7: =VLOOKUP($B$5:$B$16,'PLATE COUNT-D-MESS'!$B$4:$G$15,2,0) -> 1360 | D7: =VLOOKUP($B$5:$B$16,'FOOD WASTAGE-D-MESS'!$B$4:$G$15,2,0) -> 15 | E7: =SUM(D7/C7*100) -> 1.1029412 | F7: =VLOOKUP($B$5:$B$16,'PLATE COUNT-D-MESS'!$B$4:$G$15,3,0) -> 1655 | G7: =VLOOKUP($B$5:$B$16,'FOOD WASTAGE-D-MESS'!$B$4:$G$15,3,0) -> 30 | H7: =SUM(G7/F7*100) -> 1.8126888 | I7: =VLOOKUP($B$5:$B$16,'PLATE COUNT-D-MESS'!$B$4:$G$15,4,0) -> 840 | J7: =VLOOKUP($B$5:$B$16,'FOOD WASTAGE-D-MESS'!$B$4:$G$15,4,0) -> 0 | K7: =IFERROR(SUM(I7/J7),"0") -> 0 | L7: =VLOOKUP($B$5:$B$16,'PLATE COUNT-D-MESS'!$B$4:$G$15,5,0) -> 840 | M7: =VLOOKUP($B$5:$B$16,'FOOD WASTAGE-D-MESS'!$B$4:$G$15,5,0) -> 0 | N7: =SUM(M7/L7*100) -> 0 | P7: May-2023 | Q7: =VLOOKUP($P$6:$P$17,$B$4:$N$16,4,0) -> 4.220297 | R7: =VLOOKUP($P$6:$P$17,$B$4:$N$16,7,0) -> 10.138465 | S7: =VLOOKUP($P$6:$P$17,$B$4:$N$16,10,0) -> 0 | T7: =VLOOKUP($P$6:$P$17,$B$4:$N$16,13,0) -> 11.581058 | U7: =SUM(Q7:T7)/4 -> 6.4849551
A8: 4 | B8: Jul-2023 | C8: =VLOOKUP($B$5:$B$16,'PLATE COUNT-D-MESS'!$B$4:$G$15,2,0) -> 12465 | D8: =VLOOKUP($B$5:$B$16,'FOOD WASTAGE-D-MESS'!$B$4:$G$15,2,0) -> 408 | E8: =SUM(D8/C8*100) -> 3.2731649 | F8: =VLOOKUP($B$5:$B$16,'PLATE COUNT-D-MESS'!$B$4:$G$15,3,0) -> 19740 | G8: =VLOOKUP($B$5:$B$16,'FOOD WASTAGE-D-MESS'!$B$4:$G$15,3,0) -> 1095 | H8: =SUM(G8/F8*100) -> 5.5471125 | I8: =VLOOKUP($B$5:$B$16,'PLATE COUNT-D-MESS'!$B$4:$G$15,4,0) -> 21090 | J8: =VLOOKUP($B$5:$B$16,'FOOD WASTAGE-D-MESS'!$B$4:$G$15,4,0) -> 0 | K8: =IFERROR(SUM(I8/J8),"0") -> 0 | L8: =VLOOKUP($B$5:$B$16,'PLATE COUNT-D-MESS'!$B$4:$G$15,5,0) -> 21090 | M8: =VLOOKUP($B$5:$B$16,'FOOD WASTAGE-D-MESS'!$B$4:$G$15,5,0) -> 1117 | N8: =SUM(M8/L8*100) -> 5.296349 | P8: Jun-2023 | Q8: =VLOOKUP($P$6:$P$17,$B$4:$N$16,4,0) -> 1.1029412 | R8: =VLOOKUP($P$6:$P$17,$B$4:$N$16,7,0) -> 1.8126888 | S8: =VLOOKUP($P$6:$P$17,$B$4:$N$16,10,0) -> 0 | T8: =VLOOKUP($P$6:$P$17,$B$4:$N$16,13,0) -> 0 | U8: =SUM(Q8:T8)/4 -> 0.7289075
A9: 5 | B9: Aug-2023 | C9: =VLOOKUP($B$5:$B$16,'PLATE COUNT-D-MESS'!$B$4:$G$15,2,0) -> 24580 | D9: =VLOOKUP($B$5:$B$16,'FOOD WASTAGE-D-MESS'!$B$4:$G$15,2,0) -> 1181 | E9: =SUM(D9/C9*100) -> 4.8047193 | F9: =VLOOKUP($B$5:$B$16,'PLATE COUNT-D-MESS'!$B$4:$G$15,3,0) -> 40135 | G9: =VLOOKUP($B$5:$B$16,'FOOD WASTAGE-D-MESS'!$B$4:$G$15,3,0) -> 2453 | H9: =SUM(G9/F9*100) -> 6.1118724 | I9: =VLOOKUP($B$5:$B$16,'PLATE COUNT-D-MESS'!$B$4:$G$15,4,0) -> 43220 | J9: =VLOOKUP($B$5:$B$16,'FOOD WASTAGE-D-MESS'!$B$4:$G$15,4,0) -> 0 | K9: =IFERROR(SUM(I9/J9),"0") -> 0 | L9: =VLOOKUP($B$5:$B$16,'PLATE COUNT-D-MESS'!$B$4:$G$15,5,0) -> 43100 | M9: =VLOOKUP($B$5:$B$16,'FOOD WASTAGE-D-MESS'!$B$4:$G$15,5,0) -> 2479 | N9: =SUM(M9/L9*100) -> 5.7517401 | P9: Jul-2023 | Q9: =VLOOKUP($P$6:$P$17,$B$4:$N$16,4,0) -> 3.2731649 | R9: =VLOOKUP($P$6:$P$17,$B$4:$N$16,7,0) -> 5.5471125 | S9: =VLOOKUP($P$6:$P$17,$B$4:$N$16,10,0) -> 0 | T9: =VLOOKUP($P$6:$P$17,$B$4:$N$16,13,0) -> 5.296349 | U9: =SUM(Q9:T9)/4 -> 3.5291566
A10: 6 | B10: Sep-2023 | C10: =VLOOKUP($B$5:$B$16,'PLATE COUNT-D-MESS'!$B$4:$G$15,2,0) -> 22752 | D10: =VLOOKUP($B$5:$B$16,'FOOD WASTAGE-D-MESS'!$B$4:$G$15,2,0) -> 1821 | E10: =SUM(D10/C10*100) -> 8.003692 | F10: =VLOOKUP($B$5:$B$16,'PLATE COUNT-D-MESS'!$B$4:$G$15,3,0) -> 37614 | G10: =VLOOKUP($B$5:$B$16,'FOOD WASTAGE-D-MESS'!$B$4:$G$15,3,0) -> 3057 | H10: =SUM(G10/F10*100) -> 8.127293 | I10: =VLOOKUP($B$5:$B$16,'PLATE COUNT-D-MESS'!$B$4:$G$15,4,0) -> 42907 | J10: =VLOOKUP($B$5:$B$16,'FOOD WASTAGE-D-MESS'!$B$4:$G$15,4,0) -> 0 | K10: =IFERROR(SUM(I10/J10),"0") -> 0 | L10: =VLOOKUP($B$5:$B$16,'PLATE COUNT-D-MESS'!$B$4:$G$15,5,0) -> 44457 | M10: =VLOOKUP($B$5:$B$16,'FOOD WASTAGE-D-MESS'!$B$4:$G$15,5,0) -> 3583 | N10: =SUM(M10/L10*100) -> 8.0594732 | P10: Aug-2023 | Q10: =VLOOKUP($P$6:$P$17,$B$4:$N$16,4,0) -> 4.8047193 | R10: =VLOOKUP($P$6:$P$17,$B$4:$N$16,7,0) -> 6.1118724 | S10: =VLOOKUP($P$6:$P$17,$B$4:$N$16,10,0) -> 0 | T10: =VLOOKUP($P$6:$P$17,$B$4:$N$16,13,0) -> 5.7517401 | U10: =SUM(Q10:T10)/4 -> 4.167083
A11: 7 | B11: Oct-2023 | C11: =VLOOKUP($B$5:$B$16,'PLATE COUNT-D-MESS'!$B$4:$G$15,2,0) -> 13135 | D11: =VLOOKUP($B$5:$B$16,'FOOD WASTAGE-D-MESS'!$B$4:$G$15,2,0) -> 745 | E11: =SUM(D11/C11*100) -> 5.6718691 | F11: =VLOOKUP($B$5:$B$16,'PLATE COUNT-D-MESS'!$B$4:$G$15,3,0) -> 24626 | G11: =VLOOKUP($B$5:$B$16,'FOOD WASTAGE-D-MESS'!$B$4:$G$15,3,0) -> 2194 | H11: =SUM(G11/F11*100) -> 8.9092829 | I11: =VLOOKUP($B$5:$B$16,'PLATE COUNT-D-MESS'!$B$4:$G$15,4,0) -> 24790 | J11: =VLOOKUP($B$5:$B$16,'FOOD WASTAGE-D-MESS'!$B$4:$G$15,4,0) -> 0 | K11: =IFERROR(SUM(I11/J11),"0") -> 0 | L11: =VLOOKUP($B$5:$B$16,'PLATE COUNT-D-MESS'!$B$4:$G$15,5,0) -> 26240 | M11: =VLOOKUP($B$5:$B$16,'FOOD WASTAGE-D-MESS'!$B$4:$G$15,5,0) -> 2264 | N11: =SUM(M11/L11*100) -> 8.6280488 | P11: Sep-2023 | Q11: =VLOOKUP($P$6:$P$17,$B$4:$N$16,4,0) -> 8.003692 | R11: =VLOOKUP($P$6:$P$17,$B$4:$N$16,7,0) -> 8.127293 | S11: =VLOOKUP($P$6:$P$17,$B$4:$N$16,10,0) -> 0 | T11: =VLOOKUP($P$6:$P$17,$B$4:$N$16,13,0) -> 8.0594732 | U11: =SUM(Q11:T11)/4 -> 6.0476146
A12: 8 | B12: Nov-2023 | C12: =VLOOKUP($B$5:$B$16,'PLATE COUNT-D-MESS'!$B$4:$G$15,2,0) -> 12493 | D12: =VLOOKUP($B$5:$B$16,'FOOD WASTAGE-D-MESS'!$B$4:$G$15,2,0) -> 1006 | E12: =SUM(D12/C12*100) -> 8.0525094 | F12: =VLOOKUP($B$5:$B$16,'PLATE COUNT-D-MESS'!$B$4:$G$15,3,0) -> 21964 | G12: =VLOOKUP($B$5:$B$16,'FOOD WASTAGE-D-MESS'!$B$4:$G$15,3,0) -> 1977 | H12: =SUM(G12/F12*100) -> 9.0010927 | I12: =VLOOKUP($B$5:$B$16,'PLATE COUNT-D-MESS'!$B$4:$G$15,4,0) -> 26996 | J12: =VLOOKUP($B$5:$B$16,'FOOD WASTAGE-D-MESS'!$B$4:$G$15,4,0) -> 0 | K12: =IFERROR(SUM(I12/J12),"0") -> 0 | L12: =VLOOKUP($B$5:$B$16,'PLATE COUNT-D-MESS'!$B$4:$G$15,5,0) -> 26996 | M12: =VLOOKUP($B$5:$B$16,'FOOD WASTAGE-D-MESS'!$B$4:$G$15,5,0) -> 2411 | N12: =SUM(M12/L12*100) -> 8.9309527 | P12: Oct-2023 | Q12: =VLOOKUP($P$6:$P$17,$B$4:$N$16,4,0) -> 5.6718691 | R12: =VLOOKUP($P$6:$P$17,$B$4:$N$16,7,0) -> 8.9092829 | S12: =VLOOKUP($P$6:$P$17,$B$4:$N$16,10,0) -> 0 | T12: =VLOOKUP($P$6:$P$17,$B$4:$N$16,13,0) -> 8.6280488 | U12: =SUM(Q12:T12)/4 -> 5.8023002
A13: 9 | B13: Dec-2023 | C13: =VLOOKUP($B$5:$B$16,'PLATE COUNT-D-MESS'!$B$4:$G$15,2,0) -> 4976 | D13: =VLOOKUP($B$5:$B$16,'FOOD WASTAGE-D-MESS'!$B$4:$G$15,2,0) -> 205 | E13: =SUM(D13/C13*100) -> 4.1197749 | F13: =VLOOKUP($B$5:$B$16,'PLATE COUNT-D-MESS'!$B$4:$G$15,3,0) -> 8673 | G13: =VLOOKUP($B$5:$B$16,'FOOD WASTAGE-D-MESS'!$B$4:$G$15,3,0) -> 468 | H13: =SUM(G13/F13*100) -> 5.3960567 | I13: =VLOOKUP($B$5:$B$16,'PLATE COUNT-D-MESS'!$B$4:$G$15,4,0) -> 10715 | J13: =VLOOKUP($B$5:$B$16,'FOOD WASTAGE-D-MESS'!$B$4:$G$15,4,0) -> 0 | K13: =IFERROR(SUM(I13/J13),"0") -> 0 | L13: =VLOOKUP($B$5:$B$16,'PLATE COUNT-D-MESS'!$B$4:$G$15,5,0) -> 10715 | M13: =VLOOKUP($B$5:$B$16,'FOOD WASTAGE-D-MESS'!$B$4:$G$15,5,0) -> 525 | N13: =SUM(M13/L13*100) -> 4.8996734 | P13: Nov-2023 | Q13: =VLOOKUP($P$6:$P$17,$B$4:$N$16,4,0) -> 8.0525094 | R13: =VLOOKUP($P$6:$P$17,$B$4:$N$16,7,0) -> 9.0010927 | S13: =VLOOKUP($P$6:$P$17,$B$4:$N$16,10,0) -> 0 | T13: =VLOOKUP($P$6:$P$17,$B$4:$N$16,13,0) -> 8.9309527 | U13: =SUM(Q13:T13)/4 -> 6.4961387
A14: 10 | B14: Jan-2024 | C14: =VLOOKUP($B$5:$B$16,'PLATE COUNT-D-MESS'!$B$4:$G$15,2,0) -> 1395 | D14: =VLOOKUP($B$5:$B$16,'FOOD WASTAGE-D-MESS'!$B$4:$G$15,2,0) -> 0 | E14: =SUM(D14/C14*100) -> 0 | F14: =VLOOKUP($B$5:$B$16,'PLATE COUNT-D-MESS'!$B$4:$G$15,3,0) -> 1250 | G14: =VLOOKUP($B$5:$B$16,'FOOD WASTAGE-D-MESS'!$B$4:$G$15,3,0) -> 0 | H14: =SUM(G14/F14*100) -> 0 | I14: =VLOOKUP($B$5:$B$16,'PLATE COUNT-D-MESS'!$B$4:$G$15,4,0) -> 3480 | J14: =VLOOKUP($B$5:$B$16,'FOOD WASTAGE-D-MESS'!$B$4:$G$15,4,0) -> 0 | K14: =IFERROR(SUM(I14/J14),"0") -> 0 | L14: =VLOOKUP($B$5:$B$16,'PLATE COUNT-D-MESS'!$B$4:$G$15,5,0) -> 3480 | M14: =VLOOKUP($B$5:$B$16,'FOOD WASTAGE-D-MESS'!$B$4:$G$15,5,0) -> 0 | N14: =SUM(M14/L14*100) -> 0 | P14: Dec-2023 | Q14: =VLOOKUP($P$6:$P$17,$B$4:$N$16,4,0) -> 4.1197749 | R14: =VLOOKUP($P$6:$P$17,$B$4:$N$16,7,0) -> 5.3960567 | S14: =VLOOKUP($P$6:$P$17,$B$4:$N$16,10,0) -> 0 | T14: =VLOOKUP($P$6:$P$17,$B$4:$N$16,13,0) -> 4.8996734 | U14: =SUM(Q14:T14)/4 -> 3.6038763
A15: 11 | B15: Feb-2024 | C15: =VLOOKUP($B$5:$B$16,'PLATE COUNT-D-MESS'!$B$4:$G$15,2,0) -> 22356 | D15: =VLOOKUP($B$5:$B$16,'FOOD WASTAGE-D-MESS'!$B$4:$G$15,2,0) -> 887 | E15: =SUM(D15/C15*100) -> 3.967615 | F15: =VLOOKUP($B$5:$B$16,'PLATE COUNT-D-MESS'!$B$4:$G$15,3,0) -> 43656 | G15: =VLOOKUP($B$5:$B$16,'FOOD WASTAGE-D-MESS'!$B$4:$G$15,3,0) -> 1680 | H15: =SUM(G15/F15*100) -> 3.8482683 | I15: =VLOOKUP($B$5:$B$16,'PLATE COUNT-D-MESS'!$B$4:$G$15,4,0) -> 51643 | J15: =VLOOKUP($B$5:$B$16,'FOOD WASTAGE-D-MESS'!$B$4:$G$15,4,0) -> 0 | K15: =IFERROR(SUM(I15/J15),"0") -> 0 | L15: =VLOOKUP($B$5:$B$16,'PLATE COUNT-D-MESS'!$B$4:$G$15,5,0) -> 51643 | M15: =VLOOKUP($B$5:$B$16,'FOOD WASTAGE-D-MESS'!$B$4:$G$15,5,0) -> 1867 | N15: =SUM(M15/L15*100) -> 3.6152044 | P15: Jan-2024 | Q15: =VLOOKUP($P$6:$P$17,$B$4:$N$16,4,0) -> 0 | R15: =VLOOKUP($P$6:$P$17,$B$4:$N$16,7,0) -> 0 | S15: =VLOOKUP($P$6:$P$17,$B$4:$N$16,10,0) -> 0 | T15: =VLOOKUP($P$6:$P$17,$B$4:$N$16,13,0) -> 0 | U15: =SUM(Q15:T15)/4 -> 0
A16: 12 | B16: Mar-2024 | C16: =VLOOKUP($B$5:$B$16,'PLATE COUNT-D-MESS'!$B$4:$G$15,2,0) -> 21414 | D16: =VLOOKUP($B$5:$B$16,'FOOD WASTAGE-D-MESS'!$B$4:$G$15,2,0) -> 1013 | E16: =SUM(D16/C16*100) -> 4.7305501 | F16: =VLOOKUP($B$5:$B$16,'PLATE COUNT-D-MESS'!$B$4:$G$15,3,0) -> 49248 | G16: =VLOOKUP($B$5:$B$16,'FOOD WASTAGE-D-MESS'!$B$4:$G$15,3,0) -> 1720 | H16: =SUM(G16/F16*100) -> 3.4925276 | I16: =VLOOKUP($B$5:$B$16,'PLATE COUNT-D-MESS'!$B$4:$G$15,4,0) -> 47967 | J16: =VLOOKUP($B$5:$B$16,'FOOD WASTAGE-D-MESS'!$B$4:$G$15,4,0) -> 0 | K16: =IFERROR(SUM(I16/J16),"0") -> 0 | L16: =VLOOKUP($B$5:$B$16,'PLATE COUNT-D-MESS'!$B$4:$G$15,5,0) -> 47967 | M16: =VLOOKUP($B$5:$B$16,'FOOD WASTAGE-D-MESS'!$B$4:$G$15,5,0) -> 2248 | N16: =SUM(M16/L16*100) -> 4.6865553 | P16: Feb-2024 | Q16: =VLOOKUP($P$6:$P$17,$B$4:$N$16,4,0) -> 3.967615 | R16: =VLOOKUP($P$6:$P$17,$B$4:$N$16,7,0) -> 3.8482683 | S16: =VLOOKUP($P$6:$P$17,$B$4:$N$16,10,0) -> 0 | T16: =VLOOKUP($P$6:$P$17,$B$4:$N$16,13,0) -> 3.6152044 | U16: =SUM(Q16:T16)/4 -> 2.8577719
B17: Grand Total | C17: =SUBTOTAL(9,C4:C16) -> 185621 | D17: =SUBTOTAL(9,D4:D16) -> 9310 | E17: =SUBTOTAL(9,E4:E16) -> 52.060811 | F17: =SUBTOTAL(9,F4:F16) -> 309813 | G17: =SUBTOTAL(9,G4:G16) -> 20859 | H17: =SUBTOTAL(9,H4:H16) -> 72.44353 | I17: =SUBTOTAL(9,I4:I16) -> 337413 | J17: =SUBTOTAL(9,J4:J16) -> 0 | ... N17: =SUBTOTAL(9,N4:N16) -> 71.573417 | P17: Mar-2024 | Q17: =VLOOKUP($P$6:$P$17,$B$4:$N$16,4,0) -> 4.7305501 | R17: =VLOOKUP($P$6:$P$17,$B$4:$N$16,7,0) -> 3.4925276 | S17: =VLOOKUP($P$6:$P$17,$B$4:$N$16,10,0) -> 0 | T17: =VLOOKUP($P$6:$P$17,$B$4:$N$16,13,0) -> 4.6865553 | U17: =SUM(Q17:T17)/4 -> 3.2274083
P18: YEAR WISE FOOE WASTAGE -D-MESS (APRIL TO MARCH-2023 TO 2024) | U18: =SUM(U6:U17)/(12) -> 4.0849533

Sheet FOOD WASTAGE-SENBAGAM MESS
A1: FOOD WASTAGE REPORT-APRIL TO MARCH-2023-2024
A2: MESS WISE REPORT-SENBAGAM MESS
A3: S.NO | B3: MONTH WISE | C3: Break Fast | D3: Lunch | E3: Snacks with Tea | F3: Dinner | G3: TOTAL FOOD WASTAGE
A4: 1 | B4: Apr-2023 | C4: 1131 | D4: 2109 | E4: 0 | F4: 1918 | G4: =SUM(C4:F4) -> 5158
A5: 2 | B5: May-2023 | C5: 1101 | D5: 1559 | E5: 0 | F5: 2017 | G5: =SUM(C5:F5) -> 4677
A6: 3 | B6: Jun-2023 | C6: 552 | D6: 834 | E6: 0 | F6: 903 | G6: =SUM(C6:F6) -> 2289
A7: 4 | B7: Jul-2023 | C7: 692 | D7: 983 | E7: 0 | F7: 1171 | G7: =SUM(C7:F7) -> 2846
A8: 5 | B8: Aug-2023 | C8: 926 | D8: 1180 | E8: 0 | F8: 1454 | G8: =SUM(C8:F8) -> 3560
A9: 6 | B9: Sep-2023 | C9: 768 | D9: 1160 | E9: 0 | F9: 1434 | G9: =SUM(C9:F9) -> 3362
A10: 7 | B10: Oct-2023 | C10: 767 | D10: 1162 | E10: 0 | F10: 1428 | G10: =SUM(C10:F10) -> 3357
A11: 8 | B11: Nov-2023 | C11: 656 | D11: 1094 | E11: 0 | F11: 1241 | G11: =SUM(C11:F11) -> 2991
A12: 9 | B12: Dec-2023 | C12: 389 | D12: 659 | E12: 0 | F12: 838 | G12: =SUM(C12:F12) -> 1886
A13: 10 | B13: Jan-2024 | C13: 254 | D13: 424 | E13: 0 | F13: 530 | G13: =SUM(C13:F13) -> 1208
A14: 11 | B14: Feb-2024 | C14: 532 | D14: 971 | E14: 0 | F14: 1156 | G14: =SUM(C14:F14) -> 2659
A15: 12 | B15: Mar-2024 | C15: 596 | D15: 1096 | E15: 0 | F15: 1246 | G15: =SUM(C15:F15) -> 2938
B16: Grand Total | C16: =SUBTOTAL(9,C4:C15) -> 8364 | D16: =SUBTOTAL(9,D4:D15) -> 13231 | E16: =SUBTOTAL(9,E4:E15) -> 0 | F16: =SUBTOTAL(9,F4:F15) -> 15336 | G16: =SUBTOTAL(9,G4:G15) -> 36931

Sheet PLATE COUNT-SENBAGAM MESS
A1: STUDENT PLATE COUNT REPORT-APRIL TO MARCH-2023-2024
A2: PLATE COUNT REPORT-SENBAGAM MESS
A3: S.NO | B3: Break Fast | C3: Break Fast | D3: Lunch | E3: Snacks with Tea | F3: Dinner | G3: Total Plate Count
A4: 1 | B4: Apr-2023 | C4: 18560 | D4: 23780 | E4: 25070 | F4: 24990 | G4: =SUM(C4:F4) -> 92400
A5: 2 | B5: May-2023 | C5: 19820 | D5: 22415 | E5: 24565 | F5: 24155 | G5: =SUM(C5:F5) -> 90955
A6: 3 | B6: Jun-2023 | C6: 9630 | D6: 10435 | E6: 11113 | F6: 11048 | G6: =SUM(C6:F6) -> 42226
A7: 4 | B7: Jul-2023 | C7: 18070 | D7: 20685 | E7: 22218 | F7: 22218 | G7: =SUM(C7:F7) -> 83191
A8: 5 | B8: Aug-2023 | C8: 28621 | D8: 33720 | E8: 37262 | F8: 37262 | G8: =SUM(C8:F8) -> 136865
A9: 6 | B9: Sep-2023 | C9: 25850 | D9: 33820 | E9: 36740 | F9: 36770 | G9: =SUM(C9:F9) -> 133180
A10: 7 | B10: Oct-2023 | C10: 23980 | D10: 37370 | E10: 43070 | F10: 43070 | G10: =SUM(C10:F10) -> 147490
A11: 8 | B11: Nov-2023 | C11: 25900 | D11: 35500 | E11: 39475 | F11: 39475 | G11: =SUM(C11:F11) -> 140350
A12: 9 | B12: Dec-2023 | C12: 15635 | D12: 20235 | E12: 21520 | F12: 21640 | G12: =SUM(C12:F12) -> 79030
A13: 10 | B13: Jan-2024 | C13: 20310 | D13: 24910 | E13: 26700 | F13: 27480 | G13: =SUM(C13:F13) -> 99400
A14: 11 | B14: Feb-2024 | C14: 28741 | D14: 42120 | E14: 44180 | F14: 44180 | G14: =SUM(C14:F14) -> 159221
A15: 12 | B15: Mar-2024 | C15: 28770 | D15: 45250 | E15: 46430 | F15: 46430 | G15: =SUM(C15:F15) -> 166880
B16: Grand Total | C16: =SUBTOTAL(9,C4:C15) -> 263887 | D16: =SUBTOTAL(9,D4:D15) -> 350240 | E16: =SUBTOTAL(9,E4:E15) -> 378343 | F16: =SUBTOTAL(9,F4:F15) -> 378718 | G16: =SUBTOTAL(9,G4:G15) -> 1371188

Sheet REPORT -SENBAGAM MESS
A1: SRM IST HOSTEL MESS
A2: SENBAGAM -MESS PLATE COUNT& FOOD WASTAGE -APRIL TO MARCH-2023-2024
C3: Plate Count | D3: Food Wastage | E3: Percantage of Food Wastage % | F3: Plate Count | G3: Food Wastage | H3: Percantage of Food Wastage % | I3: Plate Count | J3: Food Wastage | K3: Percantage of Food Wastage % | L3: Plate Count | M3: Food Wastage | N3: Percantage of Food Wastage % | P3: SRM IST HOSTEL MESS
A4: S.NO | B4: MONTH WISE | C4: Break Fast | D4: Break Fast | E4: Break Fast | F4: Lunch | G4: Lunch | H4: Lunch | I4: Snacks with Tea | J4: Snacks with Tea | K4: Snacks with Tea | L4: Dinner | M4: Dinner | N4: Dinner | P4: SENBAGAM MESS-PERCEANTAGE OF FOOD WASTAGE-APRIL TO MARCH-2023 TO 2024
A5: 1 | B5: Apr-2023 | C5: =VLOOKUP($B$5:$B$16,'PLATE COUNT-SENBAGAM MESS'!$B$4:$F$15,2,0) -> 18560 | D5: =VLOOKUP($B$5:$B$16,'FOOD WASTAGE-SENBAGAM MESS'!$B$4:$G$15,2,0) -> 1131 | E5: =IFERROR(SUM(D5/C5*100),"0") -> 6.09375 | F5: =VLOOKUP($B$5:$B$16,'PLATE COUNT-SENBAGAM MESS'!$B$4:$F$15,3,0) -> 23780 | G5: =VLOOKUP($B$5:$B$16,'FOOD WASTAGE-SENBAGAM MESS'!$B$4:$G$15,3,0) -> 2109 | H5: =IFERROR(SUM(G5/F5*100),"0") -> 8.8687973 | I5: =VLOOKUP($B$5:$B$16,'PLATE COUNT-SENBAGAM MESS'!$B$4:$F$15,4,0) -> 25070 | J5: =VLOOKUP($B$5:$B$16,'FOOD WASTAGE-SENBAGAM MESS'!$B$4:$G$15,4,0) -> 0 | K5: =IFERROR(SUM(I5/J5),"0") -> 0 | L5: =VLOOKUP($B$5:$B$16,'PLATE COUNT-SENBAGAM MESS'!$B$4:$F$15,5,0) -> 24990 | M5: =VLOOKUP($B$5:$B$16,'FOOD WASTAGE-SENBAGAM MESS'!$B$4:$G$15,5,0) -> 1918 | N5: =IFERROR(SUM(M5/L5*100),"0") -> 7.67507 | P5: MONTH WISE | Q5: Break Fast | R5: Lunch | S5: Snacks with Tea | T5: Dinner | U5: MONTH WISE AVERAGE
A6: 2 | B6: May-2023 | C6: =VLOOKUP($B$5:$B$16,'PLATE COUNT-SENBAGAM MESS'!$B$4:$F$15,2,0) -> 19820 | D6: =VLOOKUP($B$5:$B$16,'FOOD WASTAGE-SENBAGAM MESS'!$B$4:$G$15,2,0) -> 1101 | E6: =IFERROR(SUM(D6/C6*100),"0") -> 5.554995 | F6: =VLOOKUP($B$5:$B$16,'PLATE COUNT-SENBAGAM MESS'!$B$4:$F$15,3,0) -> 22415 | G6: =VLOOKUP($B$5:$B$16,'FOOD WASTAGE-SENBAGAM MESS'!$B$4:$G$15,3,0) -> 1559 | H6: =IFERROR(SUM(G6/F6*100),"0") -> 6.955164 | I6: =VLOOKUP($B$5:$B$16,'PLATE COUNT-SENBAGAM MESS'!$B$4:$F$15,4,0) -> 24565 | J6: =VLOOKUP($B$5:$B$16,'FOOD WASTAGE-SENBAGAM MESS'!$B$4:$G$15,4,0) -> 0 | K6: =IFERROR(SUM(I6/J6),"0") -> 0 | L6: =VLOOKUP($B$5:$B$16,'PLATE COUNT-SENBAGAM MESS'!$B$4:$F$15,5,0) -> 24155 | M6: =VLOOKUP($B$5:$B$16,'FOOD WASTAGE-SENBAGAM MESS'!$B$4:$G$15,5,0) -> 2017 | N6: =IFERROR(SUM(M6/L6*100),"0") -> 8.350238 | P6: Apr-2023 | Q6: =VLOOKUP($P$6:$P$17,$B$4:$N$16,4,0) -> 6.09375 | R6: =VLOOKUP($P$6:$P$17,$B$4:$N$16,7,0) -> 8.8687973 | S6: =VLOOKUP($P$6:$P$17,$B$4:$N$16,10,0) -> 0 | T6: =VLOOKUP($P$6:$P$17,$B$4:$N$16,13,0) -> 7.67507 | U6: =SUM(Q6:T6)/4 -> 5.6594043
A7: 3 | B7: Jun-2023 | C7: =VLOOKUP($B$5:$B$16,'PLATE COUNT-SENBAGAM MESS'!$B$4:$F$15,2,0) -> 9630 | D7: =VLOOKUP($B$5:$B$16,'FOOD WASTAGE-SENBAGAM MESS'!$B$4:$G$15,2,0) -> 552 | E7: =IFERROR(SUM(D7/C7*100),"0") -> 5.7320872 | F7: =VLOOKUP($B$5:$B$16,'PLATE COUNT-SENBAGAM MESS'!$B$4:$F$15,3,0) -> 10435 | G7: =VLOOKUP($B$5:$B$16,'FOOD WASTAGE-SENBAGAM MESS'!$B$4:$G$15,3,0) -> 834 | H7: =IFERROR(SUM(G7/F7*100),"0") -> 7.9923335 | I7: =VLOOKUP($B$5:$B$16,'PLATE COUNT-SENBAGAM MESS'!$B$4:$F$15,4,0) -> 11113 | J7: =VLOOKUP($B$5:$B$16,'FOOD WASTAGE-SENBAGAM MESS'!$B$4:$G$15,4,0) -> 0 | K7: =IFERROR(SUM(I7/J7),"0") -> 0 | L7: =VLOOKUP($B$5:$B$16,'PLATE COUNT-SENBAGAM MESS'!$B$4:$F$15,5,0) -> 11048 | M7: =VLOOKUP($B$5:$B$16,'FOOD WASTAGE-SENBAGAM MESS'!$B$4:$G$15,5,0) -> 903 | N7: =IFERROR(SUM(M7/L7*100),"0") -> 8.1734251 | P7: May-2023 | Q7: =VLOOKUP($P$6:$P$17,$B$4:$N$16,4,0) -> 5.554995 | R7: =VLOOKUP($P$6:$P$17,$B$4:$N$16,7,0) -> 6.955164 | S7: =VLOOKUP($P$6:$P$17,$B$4:$N$16,10,0) -> 0 | T7: =VLOOKUP($P$6:$P$17,$B$4:$N$16,13,0) -> 8.350238 | U7: =SUM(Q7:T7)/4 -> 5.2150992
A8: 4 | B8: Jul-2023 | C8: =VLOOKUP($B$5:$B$16,'PLATE COUNT-SENBAGAM MESS'!$B$4:$F$15,2,0) -> 18070 | D8: =VLOOKUP($B$5:$B$16,'FOOD WASTAGE-SENBAGAM MESS'!$B$4:$G$15,2,0) -> 692 | E8: =IFERROR(SUM(D8/C8*100),"0") -> 3.8295517 | F8: =VLOOKUP($B$5:$B$16,'PLATE COUNT-SENBAGAM MESS'!$B$4:$F$15,3,0) -> 20685 | G8: =VLOOKUP($B$5:$B$16,'FOOD WASTAGE-SENBAGAM MESS'!$B$4:$G$15,3,0) -> 983 | H8: =IFERROR(SUM(G8/F8*100),"0") -> 4.7522359 | I8: =VLOOKUP($B$5:$B$16,'PLATE COUNT-SENBAGAM MESS'!$B$4:$F$15,4,0) -> 22218 | J8: =VLOOKUP($B$5:$B$16,'FOOD WASTAGE-SENBAGAM MESS'!$B$4:$G$15,4,0) -> 0 | K8: =IFERROR(SUM(I8/J8),"0") -> 0 | L8: =VLOOKUP($B$5:$B$16,'PLATE COUNT-SENBAGAM MESS'!$B$4:$F$15,5,0) -> 22218 | M8: =VLOOKUP($B$5:$B$16,'FOOD WASTAGE-SENBAGAM MESS'!$B$4:$G$15,5,0) -> 1171 | N8: =IFERROR(SUM(M8/L8*100),"0") -> 5.2705014 | P8: Jun-2023 | Q8: =VLOOKUP($P$6:$P$17,$B$4:$N$16,4,0) -> 5.7320872 | R8: =VLOOKUP($P$6:$P$17,$B$4:$N$16,7,0) -> 7.9923335 | S8: =VLOOKUP($P$6:$P$17,$B$4:$N$16,10,0) -> 0 | T8: =VLOOKUP($P$6:$P$17,$B$4:$N$16,13,0) -> 8.1734251 | U8: =SUM(Q8:T8)/4 -> 5.4744614
A9: 5 | B9: Aug-2023 | C9: =VLOOKUP($B$5:$B$16,'PLATE COUNT-SENBAGAM MESS'!$B$4:$F$15,2,0) -> 28621 | D9: =VLOOKUP($B$5:$B$16,'FOOD WASTAGE-SENBAGAM MESS'!$B$4:$G$15,2,0) -> 926 | E9: =IFERROR(SUM(D9/C9*100),"0") -> 3.2353866 | F9: =VLOOKUP($B$5:$B$16,'PLATE COUNT-SENBAGAM MESS'!$B$4:$F$15,3,0) -> 33720 | G9: =VLOOKUP($B$5:$B$16,'FOOD WASTAGE-SENBAGAM MESS'!$B$4:$G$15,3,0) -> 1180 | H9: =IFERROR(SUM(G9/F9*100),"0") -> 3.4994069 | I9: =VLOOKUP($B$5:$B$16,'PLATE COUNT-SENBAGAM MESS'!$B$4:$F$15,4,0) -> 37262 | J9: =VLOOKUP($B$5:$B$16,'FOOD WASTAGE-SENBAGAM MESS'!$B$4:$G$15,4,0) -> 0 | K9: =IFERROR(SUM(I9/J9),"0") -> 0 | L9: =VLOOKUP($B$5:$B$16,'PLATE COUNT-SENBAGAM MESS'!$B$4:$F$15,5,0) -> 37262 | M9: =VLOOKUP($B$5:$B$16,'FOOD WASTAGE-SENBAGAM MESS'!$B$4:$G$15,5,0) -> 1454 | N9: =IFERROR(SUM(M9/L9*100),"0") -> 3.9020987 | P9: Jul-2023 | Q9: =VLOOKUP($P$6:$P$17,$B$4:$N$16,4,0) -> 3.8295517 | R9: =VLOOKUP($P$6:$P$17,$B$4:$N$16,7,0) -> 4.7522359 | S9: =VLOOKUP($P$6:$P$17,$B$4:$N$16,10,0) -> 0 | T9: =VLOOKUP($P$6:$P$17,$B$4:$N$16,13,0) -> 5.2705014 | U9: =SUM(Q9:T9)/4 -> 3.4630723
A10: 6 | B10: Sep-2023 | C10: =VLOOKUP($B$5:$B$16,'PLATE COUNT-SENBAGAM MESS'!$B$4:$F$15,2,0) -> 25850 | D10: =VLOOKUP($B$5:$B$16,'FOOD WASTAGE-SENBAGAM MESS'!$B$4:$G$15,2,0) -> 768 | E10: =IFERROR(SUM(D10/C10*100),"0") -> 2.9709865 | F10: =VLOOKUP($B$5:$B$16,'PLATE COUNT-SENBAGAM MESS'!$B$4:$F$15,3,0) -> 33820 | G10: =VLOOKUP($B$5:$B$16,'FOOD WASTAGE-SENBAGAM MESS'!$B$4:$G$15,3,0) -> 1160 | H10: =IFERROR(SUM(G10/F10*100),"0") -> 3.4299231 | I10: =VLOOKUP($B$5:$B$16,'PLATE COUNT-SENBAGAM MESS'!$B$4:$F$15,4,0) -> 36740 | J10: =VLOOKUP($B$5:$B$16,'FOOD WASTAGE-SENBAGAM MESS'!$B$4:$G$15,4,0) -> 0 | K10: =IFERROR(SUM(I10/J10),"0") -> 0 | L10: =VLOOKUP($B$5:$B$16,'PLATE COUNT-SENBAGAM MESS'!$B$4:$F$15,5,0) -> 36770 | M10: =VLOOKUP($B$5:$B$16,'FOOD WASTAGE-SENBAGAM MESS'!$B$4:$G$15,5,0) -> 1434 | N10: =IFERROR(SUM(M10/L10*100),"0") -> 3.8999184 | P10: Aug-2023 | Q10: =VLOOKUP($P$6:$P$17,$B$4:$N$16,4,0) -> 3.2353866 | R10: =VLOOKUP($P$6:$P$17,$B$4:$N$16,7,0) -> 3.4994069 | S10: =VLOOKUP($P$6:$P$17,$B$4:$N$16,10,0) -> 0 | T10: =VLOOKUP($P$6:$P$17,$B$4:$N$16,13,0) -> 3.9020987 | U10: =SUM(Q10:T10)/4 -> 2.659223
A11: 7 | B11: Oct-2023 | C11: =VLOOKUP($B$5:$B$16,'PLATE COUNT-SENBAGAM MESS'!$B$4:$F$15,2,0) -> 23980 | D11: =VLOOKUP($B$5:$B$16,'FOOD WASTAGE-SENBAGAM MESS'!$B$4:$G$15,2,0) -> 767 | E11: =IFERROR(SUM(D11/C11*100),"0") -> 3.1984987 | F11: =VLOOKUP($B$5:$B$16,'PLATE COUNT-SENBAGAM MESS'!$B$4:$F$15,3,0) -> 37370 | G11: =VLOOKUP($B$5:$B$16,'FOOD WASTAGE-SENBAGAM MESS'!$B$4:$G$15,3,0) -> 1162 | H11: =IFERROR(SUM(G11/F11*100),"0") -> 3.1094461 | I11: =VLOOKUP($B$5:$B$16,'PLATE COUNT-SENBAGAM MESS'!$B$4:$F$15,4,0) -> 43070 | J11: =VLOOKUP($B$5:$B$16,'FOOD WASTAGE-SENBAGAM MESS'!$B$4:$G$15,4,0) -> 0 | K11: =IFERROR(SUM(I11/J11),"0") -> 0 | L11: =VLOOKUP($B$5:$B$16,'PLATE COUNT-SENBAGAM MESS'!$B$4:$F$15,5,0) -> 43070 | M11: =VLOOKUP($B$5:$B$16,'FOOD WASTAGE-SENBAGAM MESS'!$B$4:$G$15,5,0) -> 1428 | N11: =IFERROR(SUM(M11/L11*100),"0") -> 3.3155329 | P11: Sep-2023 | Q11: =VLOOKUP($P$6:$P$17,$B$4:$N$16,4,0) -> 2.9709865 | R11: =VLOOKUP($P$6:$P$17,$B$4:$N$16,7,0) -> 3.4299231 | S11: =VLOOKUP($P$6:$P$17,$B$4:$N$16,10,0) -> 0 | T11: =VLOOKUP($P$6:$P$17,$B$4:$N$16,13,0) -> 3.8999184 | U11: =SUM(Q11:T11)/4 -> 2.575207
A12: 8 | B12: Nov-2023 | C12: =VLOOKUP($B$5:$B$16,'PLATE COUNT-SENBAGAM MESS'!$B$4:$F$15,2,0) -> 25900 | D12: =VLOOKUP($B$5:$B$16,'FOOD WASTAGE-SENBAGAM MESS'!$B$4:$G$15,2,0) -> 656 | E12: =IFERROR(SUM(D12/C12*100),"0") -> 2.5328185 | F12: =VLOOKUP($B$5:$B$16,'PLATE COUNT-SENBAGAM MESS'!$B$4:$F$15,3,0) -> 35500 | G12: =VLOOKUP($B$5:$B$16,'FOOD WASTAGE-SENBAGAM MESS'!$B$4:$G$15,3,0) -> 1094 | H12: =IFERROR(SUM(G12/F12*100),"0") -> 3.0816901 | I12: =VLOOKUP($B$5:$B$16,'PLATE COUNT-SENBAGAM MESS'!$B$4:$F$15,4,0) -> 39475 | J12: =VLOOKUP($B$5:$B$16,'FOOD WASTAGE-SENBAGAM MESS'!$B$4:$G$15,4,0) -> 0 | K12: =IFERROR(SUM(I12/J12),"0") -> 0 | L12: =VLOOKUP($B$5:$B$16,'PLATE COUNT-SENBAGAM MESS'!$B$4:$F$15,5,0) -> 39475 | M12: =VLOOKUP($B$5:$B$16,'FOOD WASTAGE-SENBAGAM MESS'!$B$4:$G$15,5,0) -> 1241 | N12: =IFERROR(SUM(M12/L12*100),"0") -> 3.1437619 | P12: Oct-2023 | Q12: =VLOOKUP($P$6:$P$17,$B$4:$N$16,4,0) -> 3.1984987 | R12: =VLOOKUP($P$6:$P$17,$B$4:$N$16,7,0) -> 3.1094461 | S12: =VLOOKUP($P$6:$P$17,$B$4:$N$16,10,0) -> 0 | T12: =VLOOKUP($P$6:$P$17,$B$4:$N$16,13,0) -> 3.3155329 | U12: =SUM(Q12:T12)/4 -> 2.4058694
A13: 9 | B13: Dec-2023 | C13: =VLOOKUP($B$5:$B$16,'PLATE COUNT-SENBAGAM MESS'!$B$4:$F$15,2,0) -> 15635 | D13: =VLOOKUP($B$5:$B$16,'FOOD WASTAGE-SENBAGAM MESS'!$B$4:$G$15,2,0) -> 389 | E13: =IFERROR(SUM(D13/C13*100),"0") -> 2.4880077 | F13: =VLOOKUP($B$5:$B$16,'PLATE COUNT-SENBAGAM MESS'!$B$4:$F$15,3,0) -> 20235 | G13: =VLOOKUP($B$5:$B$16,'FOOD WASTAGE-SENBAGAM MESS'!$B$4:$G$15,3,0) -> 659 | H13: =IFERROR(SUM(G13/F13*100),"0") -> 3.2567334 | I13: =VLOOKUP($B$5:$B$16,'PLATE COUNT-SENBAGAM MESS'!$B$4:$F$15,4,0) -> 21520 | J13: =VLOOKUP($B$5:$B$16,'FOOD WASTAGE-SENBAGAM MESS'!$B$4:$G$15,4,0) -> 0 | K13: =IFERROR(SUM(I13/J13),"0") -> 0 | L13: =VLOOKUP($B$5:$B$16,'PLATE COUNT-SENBAGAM MESS'!$B$4:$F$15,5,0) -> 21640 | M13: =VLOOKUP($B$5:$B$16,'FOOD WASTAGE-SENBAGAM MESS'!$B$4:$G$15,5,0) -> 838 | N13: =IFERROR(SUM(M13/L13*100),"0") -> 3.8724584 | P13: Nov-2023 | Q13: =VLOOKUP($P$6:$P$17,$B$4:$N$16,4,0) -> 2.5328185 | R13: =VLOOKUP($P$6:$P$17,$B$4:$N$16,7,0) -> 3.0816901 | S13: =VLOOKUP($P$6:$P$17,$B$4:$N$16,10,0) -> 0 | T13: =VLOOKUP($P$6:$P$17,$B$4:$N$16,13,0) -> 3.1437619 | U13: =SUM(Q13:T13)/4 -> 2.1895676
A14: 10 | B14: Jan-2024 | C14: =VLOOKUP($B$5:$B$16,'PLATE COUNT-SENBAGAM MESS'!$B$4:$F$15,2,0) -> 20310 | D14: =VLOOKUP($B$5:$B$16,'FOOD WASTAGE-SENBAGAM MESS'!$B$4:$G$15,2,0) -> 254 | E14: =IFERROR(SUM(D14/C14*100),"0") -> 1.2506155 | F14: =VLOOKUP($B$5:$B$16,'PLATE COUNT-SENBAGAM MESS'!$B$4:$F$15,3,0) -> 24910 | G14: =VLOOKUP($B$5:$B$16,'FOOD WASTAGE-SENBAGAM MESS'!$B$4:$G$15,3,0) -> 424 | H14: =IFERROR(SUM(G14/F14*100),"0") -> 1.7021277 | I14: =VLOOKUP($B$5:$B$16,'PLATE COUNT-SENBAGAM MESS'!$B$4:$F$15,4,0) -> 26700 | J14: =VLOOKUP($B$5:$B$16,'FOOD WASTAGE-SENBAGAM MESS'!$B$4:$G$15,4,0) -> 0 | K14: =IFERROR(SUM(I14/J14),"0") -> 0 | L14: =VLOOKUP($B$5:$B$16,'PLATE COUNT-SENBAGAM MESS'!$B$4:$F$15,5,0) -> 27480 | M14: =VLOOKUP($B$5:$B$16,'FOOD WASTAGE-SENBAGAM MESS'!$B$4:$G$15,5,0) -> 530 | N14: =IFERROR(SUM(M14/L14*100),"0") -> 1.9286754 | P14: Dec-2023 | Q14: =VLOOKUP($P$6:$P$17,$B$4:$N$16,4,0) -> 2.4880077 | R14: =VLOOKUP($P$6:$P$17,$B$4:$N$16,7,0) -> 3.2567334 | S14: =VLOOKUP($P$6:$P$17,$B$4:$N$16,10,0) -> 0 | T14: =VLOOKUP($P$6:$P$17,$B$4:$N$16,13,0) -> 3.8724584 | U14: =SUM(Q14:T14)/4 -> 2.4042999
A15: 11 | B15: Feb-2024 | C15: =VLOOKUP($B$5:$B$16,'PLATE COUNT-SENBAGAM MESS'!$B$4:$F$15,2,0) -> 28741 | D15: =VLOOKUP($B$5:$B$16,'FOOD WASTAGE-SENBAGAM MESS'!$B$4:$G$15,2,0) -> 532 | E15: =IFERROR(SUM(D15/C15*100),"0") -> 1.8510142 | F15: =VLOOKUP($B$5:$B$16,'PLATE COUNT-SENBAGAM MESS'!$B$4:$F$15,3,0) -> 42120 | G15: =VLOOKUP($B$5:$B$16,'FOOD WASTAGE-SENBAGAM MESS'!$B$4:$G$15,3,0) -> 971 | H15: =IFERROR(SUM(G15/F15*100),"0") -> 2.3053181 | I15: =VLOOKUP($B$5:$B$16,'PLATE COUNT-SENBAGAM MESS'!$B$4:$F$15,4,0) -> 44180 | J15: =VLOOKUP($B$5:$B$16,'FOOD WASTAGE-SENBAGAM MESS'!$B$4:$G$15,4,0) -> 0 | K15: =IFERROR(SUM(I15/J15),"0") -> 0 | L15: =VLOOKUP($B$5:$B$16,'PLATE COUNT-SENBAGAM MESS'!$B$4:$F$15,5,0) -> 44180 | M15: =VLOOKUP($B$5:$B$16,'FOOD WASTAGE-SENBAGAM MESS'!$B$4:$G$15,5,0) -> 1156 | N15: =IFERROR(SUM(M15/L15*100),"0") -> 2.6165686 | P15: Jan-2024 | Q15: =VLOOKUP($P$6:$P$17,$B$4:$N$16,4,0) -> 1.2506155 | R15: =VLOOKUP($P$6:$P$17,$B$4:$N$16,7,0) -> 1.7021277 | S15: =VLOOKUP($P$6:$P$17,$B$4:$N$16,10,0) -> 0 | T15: =VLOOKUP($P$6:$P$17,$B$4:$N$16,13,0) -> 1.9286754 | U15: =SUM(Q15:T15)/4 -> 1.2203546
A16: 12 | B16: Mar-2024 | C16: =VLOOKUP($B$5:$B$16,'PLATE COUNT-SENBAGAM MESS'!$B$4:$F$15,2,0) -> 28770 | D16: =VLOOKUP($B$5:$B$16,'FOOD WASTAGE-SENBAGAM MESS'!$B$4:$G$15,2,0) -> 596 | E16: =IFERROR(SUM(D16/C16*100),"0") -> 2.0716024 | F16: =VLOOKUP($B$5:$B$16,'PLATE COUNT-SENBAGAM MESS'!$B$4:$F$15,3,0) -> 45250 | G16: =VLOOKUP($B$5:$B$16,'FOOD WASTAGE-SENBAGAM MESS'!$B$4:$G$15,3,0) -> 1096 | H16: =IFERROR(SUM(G16/F16*100),"0") -> 2.4220994 | I16: =VLOOKUP($B$5:$B$16,'PLATE COUNT-SENBAGAM MESS'!$B$4:$F$15,4,0) -> 46430 | J16: =VLOOKUP($B$5:$B$16,'FOOD WASTAGE-SENBAGAM MESS'!$B$4:$G$15,4,0) -> 0 | K16: =IFERROR(SUM(I16/J16),"0") -> 0 | L16: =VLOOKUP($B$5:$B$16,'PLATE COUNT-SENBAGAM MESS'!$B$4:$F$15,5,0) -> 46430 | M16: =VLOOKUP($B$5:$B$16,'FOOD WASTAGE-SENBAGAM MESS'!$B$4:$G$15,5,0) -> 1246 | N16: =IFERROR(SUM(M16/L16*100),"0") -> 2.6836097 | P16: Feb-2024 | Q16: =VLOOKUP($P$6:$P$17,$B$4:$N$16,4,0) -> 1.8510142 | R16: =VLOOKUP($P$6:$P$17,$B$4:$N$16,7,0) -> 2.3053181 | S16: =VLOOKUP($P$6:$P$17,$B$4:$N$16,10,0) -> 0 | T16: =VLOOKUP($P$6:$P$17,$B$4:$N$16,13,0) -> 2.6165686 | U16: =SUM(Q16:T16)/4 -> 1.6932252
B17: Grand Total | C17: =SUBTOTAL(9,C4:C16) -> 263887 | D17: =SUBTOTAL(9,D4:D16) -> 8364 | E17: =SUBTOTAL(9,E4:E16) -> 40.809314 | F17: =SUBTOTAL(9,F4:F16) -> 350240 | G17: =SUBTOTAL(9,G4:G16) -> 13231 | H17: =SUBTOTAL(9,H4:H16) -> 51.375276 | I17: =SUBTOTAL(9,I4:I16) -> 378343 | J17: =SUBTOTAL(9,J4:J16) -> 0 | ... N17: =SUBTOTAL(9,N4:N16) -> 54.831858 | P17: Mar-2024 | Q17: =VLOOKUP($P$6:$P$17,$B$4:$N$16,4,0) -> 2.0716024 | R17: =VLOOKUP($P$6:$P$17,$B$4:$N$16,7,0) -> 2.4220994 | S17: =VLOOKUP($P$6:$P$17,$B$4:$N$16,10,0) -> 0 | T17: =VLOOKUP($P$6:$P$17,$B$4:$N$16,13,0) -> 2.6836097 | U17: =SUM(Q17:T17)/4 -> 1.7943279
P18: YEAR WISE FOOE WASTAGE -SENBAGAM-MESS (APRIL TO MARCH-2023 TO 2024) | U18: =SUM(U6:U17)/(12) -> 3.0628427

Sheet FOOD WASTAGE-J-MESS
A1: FOOD WASTAGE REPORT-APRIL TO MARCH-2023-2024
A2: MESS WISE REPORT-J-MESS
A3: S.NO | B3: MONTH WISE | C3: Break Fast | D3: Lunch | E3: Snacks with Tea | F3: Dinner | G3: TOTAL FOOD WASTAGE
A4: 1 | B4: Apr-2023 | C4: 892 | D4: 2577 | E4: 0 | F4: 2661 | G4: =SUM(C4:F4) -> 6130
A5: 2 | B5: May-2023 | C5: 968 | D5: 2616 | E5: 0 | F5: 2750 | G5: =SUM(C5:F5) -> 6334
A6: 3 | B6: Jun-2023 | C6: 25 | D6: 71 | E6: 0 | F6: 0 | G6: =SUM(C6:F6) -> 96
A7: 4 | B7: Jul-2023 | C7: 346 | D7: 1914 | E7: 0 | F7: 1990 | G7: =SUM(C7:F7) -> 4250
A8: 5 | B8: Aug-2023 | C8: 959 | D8: 1420 | E8: 0 | F8: 1552 | G8: =SUM(C8:F8) -> 3931
A9: 6 | B9: Sep-2023 | C9: 948 | D9: 1210 | E9: 0 | F9: 1390 | G9: =SUM(C9:F9) -> 3548
A10: 7 | B10: Oct-2023 | C10: 694 | D10: 882 | E10: 0 | F10: 985 | G10: =SUM(C10:F10) -> 2561
A11: 8 | B11: Nov-2023 | C11: 734 | D11: 889 | E11: 0 | F11: 1052 | G11: =SUM(C11:F11) -> 2675
A12: 9 | B12: Dec-2023 | C12: 237 | D12: 306 | E12: 0 | F12: 436 | G12: =SUM(C12:F12) -> 979
A13: 10 | B13: Jan-2024 | C13: 121 | D13: 160 | E13: 0 | F13: 165 | G13: =SUM(C13:F13) -> 446
A14: 11 | B14: Feb-2024 | C14: 781 | D14: 890 | E14: 0 | F14: 1009 | G14: =SUM(C14:F14) -> 2680
A15: 12 | B15: Mar-2024 | C15: 898 | D15: 1066 | E15: 0 | F15: 1231 | G15: =SUM(C15:F15) -> 3195
B16: Grand Total | C16: =SUBTOTAL(9,C4:C15) -> 7603 | D16: =SUBTOTAL(9,D4:D15) -> 14001 | E16: =SUBTOTAL(9,E4:E15) -> 0 | F16: =SUBTOTAL(9,F4:F15) -> 15221 | G16: =SUBTOTAL(9,G4:G15) -> 36825

Sheet PLATE COUNT-J MESS
A1: STUDENT PLATE COUNT REPORT-APRIL TO MARCH-2023-2024
A2: PLATE COUNT REPORT-J- MESS
A3: S.NO | B3: Break Fast | C3: Break Fast | D3: Lunch | E3: Snacks with Tea | F3: Dinner | G3: Total Plate Count
A4: 1 | B4: Apr-2023 | C4: 24014 | D4: 30024 | E4: 30414 | F4: 30515 | G4: =SUM(C4:F4) -> 114967
A5: 2 | B5: May-2023 | C5: 24933 | D5: 29981 | E5: 32475 | F5: 32457 | G5: =SUM(C5:F5) -> 119846
A6: 3 | B6: Jun-2023 | C6: 689 | D6: 767 | E6: 0 | F6: 0 | G6: =SUM(C6:F6) -> 1456
A7: 4 | B7: Jul-2023 | C7: 13142 | D7: 23067 | E7: 24442 | F7: 24442 | G7: =SUM(C7:F7) -> 85093
A8: 5 | B8: Aug-2023 | C8: 27526 | D8: 43960 | E8: 45974 | F8: 45974 | G8: =SUM(C8:F8) -> 163434
A9: 6 | B9: Sep-2023 | C9: 26195 | D9: 41511 | E9: 46272 | F9: 46272 | G9: =SUM(C9:F9) -> 160250
A10: 7 | B10: Oct-2023 | C10: 26369 | D10: 43172 | E10: 45651 | F10: 45652 | G10: =SUM(C10:F10) -> 160844
A11: 8 | B11: Nov-2023 | C11: 27719 | D11: 40837 | E11: 46388 | F11: 46388 | G11: =SUM(C11:F11) -> 161332
A12: 9 | B12: Dec-2023 | C12: 8377 | D12: 9939 | E12: 9655 | F12: 9655 | G12: =SUM(C12:F12) -> 37626
A13: 10 | B13: Jan-2024 | C13: 8000 | D13: 12378 | E13: 12944 | F13: 13894 | G13: =SUM(C13:F13) -> 47216
A14: 11 | B14: Feb-2024 | C14: 27498 | D14: 47297 | E14: 54188 | F14: 54188 | G14: =SUM(C14:F14) -> 183171
A15: 12 | B15: Mar-2024 | C15: 27497 | D15: 48611 | E15: 55935 | F15: 55805 | G15: =SUM(C15:F15) -> 187848
B16: Grand Total | C16: =SUBTOTAL(9,C4:C15) -> 241959 | D16: =SUBTOTAL(9,D4:D15) -> 371544 | E16: =SUBTOTAL(9,E4:E15) -> 404338 | F16: =SUBTOTAL(9,F4:F15) -> 405242 | G16: =SUBTOTAL(9,G4:G15) -> 1423083

Sheet REPORT -J MESS
A1: SRM IST HOSTEL MESS
A2: J -MESS PLATE COUNT& FOOD WASTAGE -APRIL TO MARCH-2023-2024
A3: SRM IST MESS PLATE COUNT-2023 To 2024 | P3: SRM IST HOSTEL MESS
A4: DESCRIPTION | C4: Plate Count | D4: Food Wastage | E4: Percantage of Food Wastage % | F4: Plate Count | G4: Food Wastage | H4: Percantage of Food Wastage % | I4: Plate Count | J4: Food Wastage | K4: Percantage of Food Wastage % | L4: Plate Count | M4: Food Wastage | N4: Percantage of Food Wastage % | P4: J- MESS-PERCEANTAGE OF FOOD WASTAGE-APRIL TO MARCH-2023 TO 2024
A5: S.NO | B5: MONTH WISE | C5: Break Fast | D5: Break Fast | E5: Break Fast | F5: Lunch | G5: Lunch | H5: Lunch | I5: Snacks with Tea | J5: Snacks with Tea | K5: Snacks with Tea | L5: Dinner | M5: Dinner | N5: Dinner | P5: MONTH WISE | Q5: Break Fast | R5: Lunch | S5: Snacks with Tea | T5: Dinner | U5: MONTH WISE AVERAGE
A6: 1 | B6: Apr-2023 | C6: =VLOOKUP($B$6:$B$17,'PLATE COUNT-J MESS'!$B$4:$F$15,2,0) -> 24014 | D6: =VLOOKUP($B$6:$B$17,'FOOD WASTAGE-J-MESS'!$B$4:$F$15,2,0) -> 892 | E6: =IFERROR(SUM(D6/C6*100),"0") -> 3.7144999 | F6: =VLOOKUP($B$6:$B$17,'PLATE COUNT-J MESS'!$B$4:$F$15,3,0) -> 30024 | G6: =VLOOKUP($B$6:$B$17,'FOOD WASTAGE-J-MESS'!$B$4:$F$15,3,0) -> 2577 | H6: =IFERROR(SUM(G6/F6*100),"0") -> 8.5831335 | I6: =VLOOKUP($B$6:$B$17,'PLATE COUNT-J MESS'!$B$4:$F$15,4,0) -> 30414 | J6: =VLOOKUP($B$6:$B$17,'FOOD WASTAGE-J-MESS'!$B$4:$F$15,4,0) -> 0 | K6: =IFERROR(SUM(I6/J6),"0") -> 0 | L6: =VLOOKUP($B$6:$B$17,'PLATE COUNT-J MESS'!$B$4:$F$15,5,0) -> 30515 | M6: =VLOOKUP($B$6:$B$17,'FOOD WASTAGE-J-MESS'!$B$4:$F$15,5,0) -> 2661 | N6: =IFERROR(SUM(M6/L6*100),"0") -> 8.7203015 | P6: Apr-2023 | Q6: =VLOOKUP($P$6:$P$17,$B$5:$N$17,4,0) -> 3.7144999 | R6: =VLOOKUP($P$6:$P$17,$B$5:$N$17,7,0) -> 8.5831335 | S6: =VLOOKUP($P$6:$P$17,$B$5:$N$17,10,0) -> 0 | T6: =VLOOKUP($P$6:$P$17,$B$5:$N$17,13,0) -> 8.7203015 | U6: =SUM(Q6:T6)/4 -> 5.2544837
A7: 2 | B7: May-2023 | C7: =VLOOKUP($B$6:$B$17,'PLATE COUNT-J MESS'!$B$4:$F$15,2,0) -> 24933 | D7: =VLOOKUP($B$6:$B$17,'FOOD WASTAGE-J-MESS'!$B$4:$F$15,2,0) -> 968 | E7: =IFERROR(SUM(D7/C7*100),"0") -> 3.8824048 | F7: =VLOOKUP($B$6:$B$17,'PLATE COUNT-J MESS'!$B$4:$F$15,3,0) -> 29981 | G7: =VLOOKUP($B$6:$B$17,'FOOD WASTAGE-J-MESS'!$B$4:$F$15,3,0) -> 2616 | H7: =IFERROR(SUM(G7/F7*100),"0") -> 8.7255262 | I7: =VLOOKUP($B$6:$B$17,'PLATE COUNT-J MESS'!$B$4:$F$15,4,0) -> 32475 | J7: =VLOOKUP($B$6:$B$17,'FOOD WASTAGE-J-MESS'!$B$4:$F$15,4,0) -> 0 | K7: =IFERROR(SUM(I7/J7),"0") -> 0 | L7: =VLOOKUP($B$6:$B$17,'PLATE COUNT-J MESS'!$B$4:$F$15,5,0) -> 32457 | M7: =VLOOKUP($B$6:$B$17,'FOOD WASTAGE-J-MESS'!$B$4:$F$15,5,0) -> 2750 | N7: =IFERROR(SUM(M7/L7*100),"0") -> 8.4727486 | P7: May-2023 | Q7: =VLOOKUP($P$6:$P$17,$B$5:$N$17,4,0) -> 3.8824048 | R7: =VLOOKUP($P$6:$P$17,$B$5:$N$17,7,0) -> 8.7255262 | S7: =VLOOKUP($P$6:$P$17,$B$5:$N$17,10,0) -> 0 | T7: =VLOOKUP($P$6:$P$17,$B$5:$N$17,13,0) -> 8.4727486 | U7: =SUM(Q7:T7)/4 -> 5.2701699
A8: 3 | B8: Jun-2023 | C8: =VLOOKUP($B$6:$B$17,'PLATE COUNT-J MESS'!$B$4:$F$15,2,0) -> 689 | D8: =VLOOKUP($B$6:$B$17,'FOOD WASTAGE-J-MESS'!$B$4:$F$15,2,0) -> 25 | E8: =IFERROR(SUM(D8/C8*100),"0") -> 3.628447 | F8: =VLOOKUP($B$6:$B$17,'PLATE COUNT-J MESS'!$B$4:$F$15,3,0) -> 767 | G8: =VLOOKUP($B$6:$B$17,'FOOD WASTAGE-J-MESS'!$B$4:$F$15,3,0) -> 71 | H8: =IFERROR(SUM(G8/F8*100),"0") -> 9.2568449 | I8: =VLOOKUP($B$6:$B$17,'PLATE COUNT-J MESS'!$B$4:$F$15,4,0) -> 0 | J8: =VLOOKUP($B$6:$B$17,'FOOD WASTAGE-J-MESS'!$B$4:$F$15,4,0) -> 0 | K8: =IFERROR(SUM(I8/J8),"0") -> 0 | L8: =VLOOKUP($B$6:$B$17,'PLATE COUNT-J MESS'!$B$4:$F$15,5,0) -> 0 | M8: =VLOOKUP($B$6:$B$17,'FOOD WASTAGE-J-MESS'!$B$4:$F$15,5,0) -> 0 | N8: =IFERROR(SUM(M8/L8*100),"0") -> 0 | P8: Jun-2023 | Q8: =VLOOKUP($P$6:$P$17,$B$5:$N$17,4,0) -> 3.628447 | R8: =VLOOKUP($P$6:$P$17,$B$5:$N$17,7,0) -> 9.2568449 | S8: =VLOOKUP($P$6:$P$17,$B$5:$N$17,10,0) -> 0 | T8: =VLOOKUP($P$6:$P$17,$B$5:$N$17,13,0) -> 0 | U8: =SUM(Q8:T8)/4 -> 3.221323
A9: 4 | B9: Jul-2023 | C9: =VLOOKUP($B$6:$B$17,'PLATE COUNT-J MESS'!$B$4:$F$15,2,0) -> 13142 | D9: =VLOOKUP($B$6:$B$17,'FOOD WASTAGE-J-MESS'!$B$4:$F$15,2,0) -> 346 | E9: =IFERROR(SUM(D9/C9*100),"0") -> 2.6327804 | F9: =VLOOKUP($B$6:$B$17,'PLATE COUNT-J MESS'!$B$4:$F$15,3,0) -> 23067 | G9: =VLOOKUP($B$6:$B$17,'FOOD WASTAGE-J-MESS'!$B$4:$F$15,3,0) -> 1914 | H9: =IFERROR(SUM(G9/F9*100),"0") -> 8.297568 | I9: =VLOOKUP($B$6:$B$17,'PLATE COUNT-J MESS'!$B$4:$F$15,4,0) -> 24442 | J9: =VLOOKUP($B$6:$B$17,'FOOD WASTAGE-J-MESS'!$B$4:$F$15,4,0) -> 0 | K9: =IFERROR(SUM(I9/J9),"0") -> 0 | L9: =VLOOKUP($B$6:$B$17,'PLATE COUNT-J MESS'!$B$4:$F$15,5,0) -> 24442 | M9: =VLOOKUP($B$6:$B$17,'FOOD WASTAGE-J-MESS'!$B$4:$F$15,5,0) -> 1990 | N9: =IFERROR(SUM(M9/L9*100),"0") -> 8.1417233 | P9: Jul-2023 | Q9: =VLOOKUP($P$6:$P$17,$B$5:$N$17,4,0) -> 2.6327804 | R9: =VLOOKUP($P$6:$P$17,$B$5:$N$17,7,0) -> 8.297568 | S9: =VLOOKUP($P$6:$P$17,$B$5:$N$17,10,0) -> 0 | T9: =VLOOKUP($P$6:$P$17,$B$5:$N$17,13,0) -> 8.1417233 | U9: =SUM(Q9:T9)/4 -> 4.7680179
